2018-03-23 15:15:19,646 mongo_db.py[line:295] ERROR 错误的日期格式:
NoneType
2018-03-23 15:27:01,775 mongo_db.py[line:295] ERROR 错误的日期格式:
NoneType
2018-03-23 17:58:10,210 security_module.py[line:1288] ERROR elasticsearch Error:
Traceback (most recent call last):
  File "/home/web/my_env/projects/sq_platform/api/user/security_module.py", line 1280, in query_report2
    res = es.search(index=prefix, doc_type="daily_report", body=filter_dict)
  File "/home/web/my_env/lib/python3.5/site-packages/elasticsearch/client/utils.py", line 76, in _wrapped
    return func(*args, params=params, **kwargs)
  File "/home/web/my_env/lib/python3.5/site-packages/elasticsearch/client/__init__.py", line 636, in search
    doc_type, '_search'), params=params, body=body)
  File "/home/web/my_env/lib/python3.5/site-packages/elasticsearch/transport.py", line 314, in perform_request
    status, headers, data = connection.perform_request(method, url, params, body, headers=headers, ignore=ignore, timeout=timeout)
  File "/home/web/my_env/lib/python3.5/site-packages/elasticsearch/connection/http_urllib3.py", line 161, in perform_request
    self._raise_error(response.status, raw_data)
  File "/home/web/my_env/lib/python3.5/site-packages/elasticsearch/connection/base.py", line 125, in _raise_error
    raise HTTP_EXCEPTIONS.get(status_code, TransportError)(status_code, error_message, additional_info)
elasticsearch.exceptions.NotFoundError: TransportError(404, 'index_not_found_exception', 'no such index')
2018-03-23 17:58:12,726 security_module.py[line:1288] ERROR elasticsearch Error:
Traceback (most recent call last):
  File "/home/web/my_env/projects/sq_platform/api/user/security_module.py", line 1280, in query_report2
    res = es.search(index=prefix, doc_type="daily_report", body=filter_dict)
  File "/home/web/my_env/lib/python3.5/site-packages/elasticsearch/client/utils.py", line 76, in _wrapped
    return func(*args, params=params, **kwargs)
  File "/home/web/my_env/lib/python3.5/site-packages/elasticsearch/client/__init__.py", line 636, in search
    doc_type, '_search'), params=params, body=body)
  File "/home/web/my_env/lib/python3.5/site-packages/elasticsearch/transport.py", line 314, in perform_request
    status, headers, data = connection.perform_request(method, url, params, body, headers=headers, ignore=ignore, timeout=timeout)
  File "/home/web/my_env/lib/python3.5/site-packages/elasticsearch/connection/http_urllib3.py", line 161, in perform_request
    self._raise_error(response.status, raw_data)
  File "/home/web/my_env/lib/python3.5/site-packages/elasticsearch/connection/base.py", line 125, in _raise_error
    raise HTTP_EXCEPTIONS.get(status_code, TransportError)(status_code, error_message, additional_info)
elasticsearch.exceptions.NotFoundError: TransportError(404, 'index_not_found_exception', 'no such index')
2018-03-23 17:58:21,340 security_module.py[line:1288] ERROR elasticsearch Error:
Traceback (most recent call last):
  File "/home/web/my_env/projects/sq_platform/api/user/security_module.py", line 1280, in query_report2
    res = es.search(index=prefix, doc_type="daily_report", body=filter_dict)
  File "/home/web/my_env/lib/python3.5/site-packages/elasticsearch/client/utils.py", line 76, in _wrapped
    return func(*args, params=params, **kwargs)
  File "/home/web/my_env/lib/python3.5/site-packages/elasticsearch/client/__init__.py", line 636, in search
    doc_type, '_search'), params=params, body=body)
  File "/home/web/my_env/lib/python3.5/site-packages/elasticsearch/transport.py", line 314, in perform_request
    status, headers, data = connection.perform_request(method, url, params, body, headers=headers, ignore=ignore, timeout=timeout)
  File "/home/web/my_env/lib/python3.5/site-packages/elasticsearch/connection/http_urllib3.py", line 161, in perform_request
    self._raise_error(response.status, raw_data)
  File "/home/web/my_env/lib/python3.5/site-packages/elasticsearch/connection/base.py", line 125, in _raise_error
    raise HTTP_EXCEPTIONS.get(status_code, TransportError)(status_code, error_message, additional_info)
elasticsearch.exceptions.NotFoundError: TransportError(404, 'index_not_found_exception', 'no such index')
2018-03-23 17:58:29,345 security_module.py[line:1288] ERROR elasticsearch Error:
Traceback (most recent call last):
  File "/home/web/my_env/projects/sq_platform/api/user/security_module.py", line 1280, in query_report2
    res = es.search(index=prefix, doc_type="daily_report", body=filter_dict)
  File "/home/web/my_env/lib/python3.5/site-packages/elasticsearch/client/utils.py", line 76, in _wrapped
    return func(*args, params=params, **kwargs)
  File "/home/web/my_env/lib/python3.5/site-packages/elasticsearch/client/__init__.py", line 636, in search
    doc_type, '_search'), params=params, body=body)
  File "/home/web/my_env/lib/python3.5/site-packages/elasticsearch/transport.py", line 314, in perform_request
    status, headers, data = connection.perform_request(method, url, params, body, headers=headers, ignore=ignore, timeout=timeout)
  File "/home/web/my_env/lib/python3.5/site-packages/elasticsearch/connection/http_urllib3.py", line 161, in perform_request
    self._raise_error(response.status, raw_data)
  File "/home/web/my_env/lib/python3.5/site-packages/elasticsearch/connection/base.py", line 125, in _raise_error
    raise HTTP_EXCEPTIONS.get(status_code, TransportError)(status_code, error_message, additional_info)
elasticsearch.exceptions.NotFoundError: TransportError(404, 'index_not_found_exception', 'no such index')
2018-03-23 18:00:23,057 security_module.py[line:1288] ERROR elasticsearch Error:
Traceback (most recent call last):
  File "/home/web/my_env/projects/sq_platform/api/user/security_module.py", line 1280, in query_report2
    res = es.search(index=prefix, doc_type="daily_report", body=filter_dict)
  File "/home/web/my_env/lib/python3.5/site-packages/elasticsearch/client/utils.py", line 76, in _wrapped
    return func(*args, params=params, **kwargs)
  File "/home/web/my_env/lib/python3.5/site-packages/elasticsearch/client/__init__.py", line 636, in search
    doc_type, '_search'), params=params, body=body)
  File "/home/web/my_env/lib/python3.5/site-packages/elasticsearch/transport.py", line 314, in perform_request
    status, headers, data = connection.perform_request(method, url, params, body, headers=headers, ignore=ignore, timeout=timeout)
  File "/home/web/my_env/lib/python3.5/site-packages/elasticsearch/connection/http_urllib3.py", line 161, in perform_request
    self._raise_error(response.status, raw_data)
  File "/home/web/my_env/lib/python3.5/site-packages/elasticsearch/connection/base.py", line 125, in _raise_error
    raise HTTP_EXCEPTIONS.get(status_code, TransportError)(status_code, error_message, additional_info)
elasticsearch.exceptions.NotFoundError: TransportError(404, 'index_not_found_exception', 'no such index')
2018-03-23 18:05:55,235 security_module.py[line:1288] ERROR elasticsearch Error:
Traceback (most recent call last):
  File "/home/web/my_env/projects/sq_platform/api/user/security_module.py", line 1280, in query_report2
    res = es.search(index=prefix, doc_type="daily_report", body=filter_dict)
  File "/home/web/my_env/lib/python3.5/site-packages/elasticsearch/client/utils.py", line 76, in _wrapped
    return func(*args, params=params, **kwargs)
  File "/home/web/my_env/lib/python3.5/site-packages/elasticsearch/client/__init__.py", line 636, in search
    doc_type, '_search'), params=params, body=body)
  File "/home/web/my_env/lib/python3.5/site-packages/elasticsearch/transport.py", line 314, in perform_request
    status, headers, data = connection.perform_request(method, url, params, body, headers=headers, ignore=ignore, timeout=timeout)
  File "/home/web/my_env/lib/python3.5/site-packages/elasticsearch/connection/http_urllib3.py", line 161, in perform_request
    self._raise_error(response.status, raw_data)
  File "/home/web/my_env/lib/python3.5/site-packages/elasticsearch/connection/base.py", line 125, in _raise_error
    raise HTTP_EXCEPTIONS.get(status_code, TransportError)(status_code, error_message, additional_info)
elasticsearch.exceptions.NotFoundError: TransportError(404, 'index_not_found_exception', 'no such index')
2018-03-23 18:08:10,501 security_module.py[line:1288] ERROR elasticsearch Error:
Traceback (most recent call last):
  File "/home/web/my_env/projects/sq_platform/api/user/security_module.py", line 1280, in query_report2
    res = es.search(index=prefix, doc_type="daily_report", body=filter_dict)
  File "/home/web/my_env/lib/python3.5/site-packages/elasticsearch/client/utils.py", line 76, in _wrapped
    return func(*args, params=params, **kwargs)
  File "/home/web/my_env/lib/python3.5/site-packages/elasticsearch/client/__init__.py", line 636, in search
    doc_type, '_search'), params=params, body=body)
  File "/home/web/my_env/lib/python3.5/site-packages/elasticsearch/transport.py", line 314, in perform_request
    status, headers, data = connection.perform_request(method, url, params, body, headers=headers, ignore=ignore, timeout=timeout)
  File "/home/web/my_env/lib/python3.5/site-packages/elasticsearch/connection/http_urllib3.py", line 161, in perform_request
    self._raise_error(response.status, raw_data)
  File "/home/web/my_env/lib/python3.5/site-packages/elasticsearch/connection/base.py", line 125, in _raise_error
    raise HTTP_EXCEPTIONS.get(status_code, TransportError)(status_code, error_message, additional_info)
elasticsearch.exceptions.NotFoundError: TransportError(404, 'index_not_found_exception', 'no such index')
2018-03-23 18:13:58,172 security_module.py[line:1288] ERROR elasticsearch Error:
Traceback (most recent call last):
  File "/home/web/my_env/projects/sq_platform/api/user/security_module.py", line 1280, in query_report2
    res = es.search(index=prefix, doc_type="daily_report", body=filter_dict)
  File "/home/web/my_env/lib/python3.5/site-packages/elasticsearch/client/utils.py", line 76, in _wrapped
    return func(*args, params=params, **kwargs)
  File "/home/web/my_env/lib/python3.5/site-packages/elasticsearch/client/__init__.py", line 636, in search
    doc_type, '_search'), params=params, body=body)
  File "/home/web/my_env/lib/python3.5/site-packages/elasticsearch/transport.py", line 314, in perform_request
    status, headers, data = connection.perform_request(method, url, params, body, headers=headers, ignore=ignore, timeout=timeout)
  File "/home/web/my_env/lib/python3.5/site-packages/elasticsearch/connection/http_urllib3.py", line 161, in perform_request
    self._raise_error(response.status, raw_data)
  File "/home/web/my_env/lib/python3.5/site-packages/elasticsearch/connection/base.py", line 125, in _raise_error
    raise HTTP_EXCEPTIONS.get(status_code, TransportError)(status_code, error_message, additional_info)
elasticsearch.exceptions.NotFoundError: TransportError(404, 'index_not_found_exception', 'no such index')
2018-03-24 13:49:24,273 security_module.py[line:1288] ERROR elasticsearch Error:
Traceback (most recent call last):
  File "/home/web/my_env/projects/sq_platform/api/user/security_module.py", line 1280, in query_report2
    res = es.search(index=prefix, doc_type="daily_report", body=filter_dict)
  File "/home/web/my_env/lib/python3.5/site-packages/elasticsearch/client/utils.py", line 76, in _wrapped
    return func(*args, params=params, **kwargs)
  File "/home/web/my_env/lib/python3.5/site-packages/elasticsearch/client/__init__.py", line 636, in search
    doc_type, '_search'), params=params, body=body)
  File "/home/web/my_env/lib/python3.5/site-packages/elasticsearch/transport.py", line 314, in perform_request
    status, headers, data = connection.perform_request(method, url, params, body, headers=headers, ignore=ignore, timeout=timeout)
  File "/home/web/my_env/lib/python3.5/site-packages/elasticsearch/connection/http_urllib3.py", line 161, in perform_request
    self._raise_error(response.status, raw_data)
  File "/home/web/my_env/lib/python3.5/site-packages/elasticsearch/connection/base.py", line 125, in _raise_error
    raise HTTP_EXCEPTIONS.get(status_code, TransportError)(status_code, error_message, additional_info)
elasticsearch.exceptions.NotFoundError: TransportError(404, 'index_not_found_exception', 'no such index')
2018-03-24 13:49:25,938 user_view.py[line:313] ERROR Error! 
Traceback (most recent call last):
  File "/home/web/my_env/projects/sq_platform/api/user/user_view.py", line 235, in update_image
    file = upload_files[key]
  File "/home/web/my_env/lib/python3.5/site-packages/werkzeug/datastructures.py", line 428, in __getitem__
    raise exceptions.BadRequestKeyError(key)
werkzeug.exceptions.HTTPException.wrap.<locals>.newcls: 400 Bad Request: The browser (or proxy) sent a request that this server could not understand.
2018-03-24 13:49:44,884 security_module.py[line:1288] ERROR elasticsearch Error:
Traceback (most recent call last):
  File "/home/web/my_env/projects/sq_platform/api/user/security_module.py", line 1280, in query_report2
    res = es.search(index=prefix, doc_type="daily_report", body=filter_dict)
  File "/home/web/my_env/lib/python3.5/site-packages/elasticsearch/client/utils.py", line 76, in _wrapped
    return func(*args, params=params, **kwargs)
  File "/home/web/my_env/lib/python3.5/site-packages/elasticsearch/client/__init__.py", line 636, in search
    doc_type, '_search'), params=params, body=body)
  File "/home/web/my_env/lib/python3.5/site-packages/elasticsearch/transport.py", line 314, in perform_request
    status, headers, data = connection.perform_request(method, url, params, body, headers=headers, ignore=ignore, timeout=timeout)
  File "/home/web/my_env/lib/python3.5/site-packages/elasticsearch/connection/http_urllib3.py", line 161, in perform_request
    self._raise_error(response.status, raw_data)
  File "/home/web/my_env/lib/python3.5/site-packages/elasticsearch/connection/base.py", line 125, in _raise_error
    raise HTTP_EXCEPTIONS.get(status_code, TransportError)(status_code, error_message, additional_info)
elasticsearch.exceptions.NotFoundError: TransportError(404, 'index_not_found_exception', 'no such index')
