2018-03-17 08:34:43,769 mongo_db.py[line:913] ERROR mongo_db.save func Error,原因:not master
Traceback (most recent call last):
  File "/home/web/my_env/projects/sq_platform/mongo_db.py", line 904, in save
    save_id = ses.save(save_dict)
  File "/home/web/my_env/lib/python3.5/site-packages/pymongo/collection.py", line 2481, in save
    collation=collation)
  File "/home/web/my_env/lib/python3.5/site-packages/pymongo/collection.py", line 767, in _update
    _check_write_command_response([(0, result)])
  File "/home/web/my_env/lib/python3.5/site-packages/pymongo/helpers.py", line 315, in _check_write_command_response
    raise WriteError(error.get("errmsg"), error.get("code"), error)
pymongo.errors.WriteError: not master
2018-03-17 08:34:43,783 mongo_db.py[line:913] ERROR mongo_db.save func Error,原因:not master
Traceback (most recent call last):
  File "/home/web/my_env/projects/sq_platform/mongo_db.py", line 904, in save
    save_id = ses.save(save_dict)
  File "/home/web/my_env/lib/python3.5/site-packages/pymongo/collection.py", line 2481, in save
    collation=collation)
  File "/home/web/my_env/lib/python3.5/site-packages/pymongo/collection.py", line 767, in _update
    _check_write_command_response([(0, result)])
  File "/home/web/my_env/lib/python3.5/site-packages/pymongo/helpers.py", line 315, in _check_write_command_response
    raise WriteError(error.get("errmsg"), error.get("code"), error)
pymongo.errors.WriteError: not master
2018-03-17 08:34:53,713 mongo_db.py[line:913] ERROR mongo_db.save func Error,原因:not master
Traceback (most recent call last):
  File "/home/web/my_env/projects/sq_platform/mongo_db.py", line 904, in save
    save_id = ses.save(save_dict)
  File "/home/web/my_env/lib/python3.5/site-packages/pymongo/collection.py", line 2481, in save
    collation=collation)
  File "/home/web/my_env/lib/python3.5/site-packages/pymongo/collection.py", line 767, in _update
    _check_write_command_response([(0, result)])
  File "/home/web/my_env/lib/python3.5/site-packages/pymongo/helpers.py", line 315, in _check_write_command_response
    raise WriteError(error.get("errmsg"), error.get("code"), error)
pymongo.errors.WriteError: not master
2018-03-17 08:34:53,719 mongo_db.py[line:913] ERROR mongo_db.save func Error,原因:not master
Traceback (most recent call last):
  File "/home/web/my_env/projects/sq_platform/mongo_db.py", line 904, in save
    save_id = ses.save(save_dict)
  File "/home/web/my_env/lib/python3.5/site-packages/pymongo/collection.py", line 2481, in save
    collation=collation)
  File "/home/web/my_env/lib/python3.5/site-packages/pymongo/collection.py", line 767, in _update
    _check_write_command_response([(0, result)])
  File "/home/web/my_env/lib/python3.5/site-packages/pymongo/helpers.py", line 315, in _check_write_command_response
    raise WriteError(error.get("errmsg"), error.get("code"), error)
pymongo.errors.WriteError: not master
2018-03-17 08:35:22,232 mongo_db.py[line:913] ERROR mongo_db.save func Error,原因:not master
Traceback (most recent call last):
  File "/home/web/my_env/projects/sq_platform/mongo_db.py", line 904, in save
    save_id = ses.save(save_dict)
  File "/home/web/my_env/lib/python3.5/site-packages/pymongo/collection.py", line 2481, in save
    collation=collation)
  File "/home/web/my_env/lib/python3.5/site-packages/pymongo/collection.py", line 767, in _update
    _check_write_command_response([(0, result)])
  File "/home/web/my_env/lib/python3.5/site-packages/pymongo/helpers.py", line 315, in _check_write_command_response
    raise WriteError(error.get("errmsg"), error.get("code"), error)
pymongo.errors.WriteError: not master
2018-03-17 08:35:22,246 mongo_db.py[line:913] ERROR mongo_db.save func Error,原因:not master
Traceback (most recent call last):
  File "/home/web/my_env/projects/sq_platform/mongo_db.py", line 904, in save
    save_id = ses.save(save_dict)
  File "/home/web/my_env/lib/python3.5/site-packages/pymongo/collection.py", line 2481, in save
    collation=collation)
  File "/home/web/my_env/lib/python3.5/site-packages/pymongo/collection.py", line 767, in _update
    _check_write_command_response([(0, result)])
  File "/home/web/my_env/lib/python3.5/site-packages/pymongo/helpers.py", line 315, in _check_write_command_response
    raise WriteError(error.get("errmsg"), error.get("code"), error)
pymongo.errors.WriteError: not master
2018-03-17 08:35:32,235 mongo_db.py[line:913] ERROR mongo_db.save func Error,原因:not master
Traceback (most recent call last):
  File "/home/web/my_env/projects/sq_platform/mongo_db.py", line 904, in save
    save_id = ses.save(save_dict)
  File "/home/web/my_env/lib/python3.5/site-packages/pymongo/collection.py", line 2481, in save
    collation=collation)
  File "/home/web/my_env/lib/python3.5/site-packages/pymongo/collection.py", line 767, in _update
    _check_write_command_response([(0, result)])
  File "/home/web/my_env/lib/python3.5/site-packages/pymongo/helpers.py", line 315, in _check_write_command_response
    raise WriteError(error.get("errmsg"), error.get("code"), error)
pymongo.errors.WriteError: not master
2018-03-17 08:35:32,250 mongo_db.py[line:913] ERROR mongo_db.save func Error,原因:not master
Traceback (most recent call last):
  File "/home/web/my_env/projects/sq_platform/mongo_db.py", line 904, in save
    save_id = ses.save(save_dict)
  File "/home/web/my_env/lib/python3.5/site-packages/pymongo/collection.py", line 2481, in save
    collation=collation)
  File "/home/web/my_env/lib/python3.5/site-packages/pymongo/collection.py", line 767, in _update
    _check_write_command_response([(0, result)])
  File "/home/web/my_env/lib/python3.5/site-packages/pymongo/helpers.py", line 315, in _check_write_command_response
    raise WriteError(error.get("errmsg"), error.get("code"), error)
pymongo.errors.WriteError: not master
2018-03-17 08:35:42,212 mongo_db.py[line:913] ERROR mongo_db.save func Error,原因:not master
Traceback (most recent call last):
  File "/home/web/my_env/projects/sq_platform/mongo_db.py", line 904, in save
    save_id = ses.save(save_dict)
  File "/home/web/my_env/lib/python3.5/site-packages/pymongo/collection.py", line 2481, in save
    collation=collation)
  File "/home/web/my_env/lib/python3.5/site-packages/pymongo/collection.py", line 767, in _update
    _check_write_command_response([(0, result)])
  File "/home/web/my_env/lib/python3.5/site-packages/pymongo/helpers.py", line 315, in _check_write_command_response
    raise WriteError(error.get("errmsg"), error.get("code"), error)
pymongo.errors.WriteError: not master
2018-03-17 08:35:42,226 mongo_db.py[line:913] ERROR mongo_db.save func Error,原因:not master
Traceback (most recent call last):
  File "/home/web/my_env/projects/sq_platform/mongo_db.py", line 904, in save
    save_id = ses.save(save_dict)
  File "/home/web/my_env/lib/python3.5/site-packages/pymongo/collection.py", line 2481, in save
    collation=collation)
  File "/home/web/my_env/lib/python3.5/site-packages/pymongo/collection.py", line 767, in _update
    _check_write_command_response([(0, result)])
  File "/home/web/my_env/lib/python3.5/site-packages/pymongo/helpers.py", line 315, in _check_write_command_response
    raise WriteError(error.get("errmsg"), error.get("code"), error)
pymongo.errors.WriteError: not master
2018-03-17 08:35:52,232 mongo_db.py[line:913] ERROR mongo_db.save func Error,原因:not master
Traceback (most recent call last):
  File "/home/web/my_env/projects/sq_platform/mongo_db.py", line 904, in save
    save_id = ses.save(save_dict)
  File "/home/web/my_env/lib/python3.5/site-packages/pymongo/collection.py", line 2481, in save
    collation=collation)
  File "/home/web/my_env/lib/python3.5/site-packages/pymongo/collection.py", line 767, in _update
    _check_write_command_response([(0, result)])
  File "/home/web/my_env/lib/python3.5/site-packages/pymongo/helpers.py", line 315, in _check_write_command_response
    raise WriteError(error.get("errmsg"), error.get("code"), error)
pymongo.errors.WriteError: not master
2018-03-17 08:35:52,245 mongo_db.py[line:913] ERROR mongo_db.save func Error,原因:not master
Traceback (most recent call last):
  File "/home/web/my_env/projects/sq_platform/mongo_db.py", line 904, in save
    save_id = ses.save(save_dict)
  File "/home/web/my_env/lib/python3.5/site-packages/pymongo/collection.py", line 2481, in save
    collation=collation)
  File "/home/web/my_env/lib/python3.5/site-packages/pymongo/collection.py", line 767, in _update
    _check_write_command_response([(0, result)])
  File "/home/web/my_env/lib/python3.5/site-packages/pymongo/helpers.py", line 315, in _check_write_command_response
    raise WriteError(error.get("errmsg"), error.get("code"), error)
pymongo.errors.WriteError: not master
2018-03-17 09:45:22,942 mongo_db.py[line:913] ERROR mongo_db.save func Error,原因:not master
Traceback (most recent call last):
  File "/home/web/my_env/projects/sq_platform/mongo_db.py", line 904, in save
    save_id = ses.save(save_dict)
  File "/home/web/my_env/lib/python3.5/site-packages/pymongo/collection.py", line 2481, in save
    collation=collation)
  File "/home/web/my_env/lib/python3.5/site-packages/pymongo/collection.py", line 767, in _update
    _check_write_command_response([(0, result)])
  File "/home/web/my_env/lib/python3.5/site-packages/pymongo/helpers.py", line 315, in _check_write_command_response
    raise WriteError(error.get("errmsg"), error.get("code"), error)
pymongo.errors.WriteError: not master
2018-03-17 09:45:22,947 mongo_db.py[line:913] ERROR mongo_db.save func Error,原因:not master
Traceback (most recent call last):
  File "/home/web/my_env/projects/sq_platform/mongo_db.py", line 904, in save
    save_id = ses.save(save_dict)
  File "/home/web/my_env/lib/python3.5/site-packages/pymongo/collection.py", line 2481, in save
    collation=collation)
  File "/home/web/my_env/lib/python3.5/site-packages/pymongo/collection.py", line 767, in _update
    _check_write_command_response([(0, result)])
  File "/home/web/my_env/lib/python3.5/site-packages/pymongo/helpers.py", line 315, in _check_write_command_response
    raise WriteError(error.get("errmsg"), error.get("code"), error)
pymongo.errors.WriteError: not master
2018-03-17 10:45:26,025 mongo_db.py[line:913] ERROR mongo_db.save func Error,原因:not master
Traceback (most recent call last):
  File "/home/web/my_env/projects/sq_platform/mongo_db.py", line 904, in save
    save_id = ses.save(save_dict)
  File "/home/web/my_env/lib/python3.5/site-packages/pymongo/collection.py", line 2481, in save
    collation=collation)
  File "/home/web/my_env/lib/python3.5/site-packages/pymongo/collection.py", line 767, in _update
    _check_write_command_response([(0, result)])
  File "/home/web/my_env/lib/python3.5/site-packages/pymongo/helpers.py", line 315, in _check_write_command_response
    raise WriteError(error.get("errmsg"), error.get("code"), error)
pymongo.errors.WriteError: not master
2018-03-17 10:45:26,030 mongo_db.py[line:913] ERROR mongo_db.save func Error,原因:not master
Traceback (most recent call last):
  File "/home/web/my_env/projects/sq_platform/mongo_db.py", line 904, in save
    save_id = ses.save(save_dict)
  File "/home/web/my_env/lib/python3.5/site-packages/pymongo/collection.py", line 2481, in save
    collation=collation)
  File "/home/web/my_env/lib/python3.5/site-packages/pymongo/collection.py", line 767, in _update
    _check_write_command_response([(0, result)])
  File "/home/web/my_env/lib/python3.5/site-packages/pymongo/helpers.py", line 315, in _check_write_command_response
    raise WriteError(error.get("errmsg"), error.get("code"), error)
pymongo.errors.WriteError: not master
2018-03-17 10:57:13,424 mongo_db.py[line:913] ERROR mongo_db.save func Error,原因:not master
Traceback (most recent call last):
  File "/home/web/my_env/projects/sq_platform/mongo_db.py", line 904, in save
    save_id = ses.save(save_dict)
  File "/home/web/my_env/lib/python3.5/site-packages/pymongo/collection.py", line 2481, in save
    collation=collation)
  File "/home/web/my_env/lib/python3.5/site-packages/pymongo/collection.py", line 767, in _update
    _check_write_command_response([(0, result)])
  File "/home/web/my_env/lib/python3.5/site-packages/pymongo/helpers.py", line 315, in _check_write_command_response
    raise WriteError(error.get("errmsg"), error.get("code"), error)
pymongo.errors.WriteError: not master
2018-03-17 10:57:13,430 mongo_db.py[line:913] ERROR mongo_db.save func Error,原因:not master
Traceback (most recent call last):
  File "/home/web/my_env/projects/sq_platform/mongo_db.py", line 904, in save
    save_id = ses.save(save_dict)
  File "/home/web/my_env/lib/python3.5/site-packages/pymongo/collection.py", line 2481, in save
    collation=collation)
  File "/home/web/my_env/lib/python3.5/site-packages/pymongo/collection.py", line 767, in _update
    _check_write_command_response([(0, result)])
  File "/home/web/my_env/lib/python3.5/site-packages/pymongo/helpers.py", line 315, in _check_write_command_response
    raise WriteError(error.get("errmsg"), error.get("code"), error)
pymongo.errors.WriteError: not master
2018-03-17 10:59:03,251 mongo_db.py[line:913] ERROR mongo_db.save func Error,原因:not master
Traceback (most recent call last):
  File "/home/web/my_env/projects/sq_platform/mongo_db.py", line 904, in save
    save_id = ses.save(save_dict)
  File "/home/web/my_env/lib/python3.5/site-packages/pymongo/collection.py", line 2481, in save
    collation=collation)
  File "/home/web/my_env/lib/python3.5/site-packages/pymongo/collection.py", line 767, in _update
    _check_write_command_response([(0, result)])
  File "/home/web/my_env/lib/python3.5/site-packages/pymongo/helpers.py", line 315, in _check_write_command_response
    raise WriteError(error.get("errmsg"), error.get("code"), error)
pymongo.errors.WriteError: not master
2018-03-17 10:59:03,256 mongo_db.py[line:913] ERROR mongo_db.save func Error,原因:not master
Traceback (most recent call last):
  File "/home/web/my_env/projects/sq_platform/mongo_db.py", line 904, in save
    save_id = ses.save(save_dict)
  File "/home/web/my_env/lib/python3.5/site-packages/pymongo/collection.py", line 2481, in save
    collation=collation)
  File "/home/web/my_env/lib/python3.5/site-packages/pymongo/collection.py", line 767, in _update
    _check_write_command_response([(0, result)])
  File "/home/web/my_env/lib/python3.5/site-packages/pymongo/helpers.py", line 315, in _check_write_command_response
    raise WriteError(error.get("errmsg"), error.get("code"), error)
pymongo.errors.WriteError: not master
2018-03-17 11:11:13,838 mongo_db.py[line:913] ERROR mongo_db.save func Error,原因:not master
Traceback (most recent call last):
  File "/home/web/my_env/projects/sq_platform/mongo_db.py", line 904, in save
    save_id = ses.save(save_dict)
  File "/home/web/my_env/lib/python3.5/site-packages/pymongo/collection.py", line 2481, in save
    collation=collation)
  File "/home/web/my_env/lib/python3.5/site-packages/pymongo/collection.py", line 767, in _update
    _check_write_command_response([(0, result)])
  File "/home/web/my_env/lib/python3.5/site-packages/pymongo/helpers.py", line 315, in _check_write_command_response
    raise WriteError(error.get("errmsg"), error.get("code"), error)
pymongo.errors.WriteError: not master
2018-03-17 11:11:13,844 mongo_db.py[line:913] ERROR mongo_db.save func Error,原因:not master
Traceback (most recent call last):
  File "/home/web/my_env/projects/sq_platform/mongo_db.py", line 904, in save
    save_id = ses.save(save_dict)
  File "/home/web/my_env/lib/python3.5/site-packages/pymongo/collection.py", line 2481, in save
    collation=collation)
  File "/home/web/my_env/lib/python3.5/site-packages/pymongo/collection.py", line 767, in _update
    _check_write_command_response([(0, result)])
  File "/home/web/my_env/lib/python3.5/site-packages/pymongo/helpers.py", line 315, in _check_write_command_response
    raise WriteError(error.get("errmsg"), error.get("code"), error)
pymongo.errors.WriteError: not master
