2018-03-26 08:56:30,961 security_module.py[line:1288] ERROR elasticsearch Error:
Traceback (most recent call last):
  File "/home/web/my_env/projects/sq_platform/api/user/security_module.py", line 1280, in query_report2
    res = es.search(index=prefix, doc_type="daily_report", body=filter_dict)
  File "/home/web/my_env/lib/python3.5/site-packages/elasticsearch/client/utils.py", line 76, in _wrapped
    return func(*args, params=params, **kwargs)
  File "/home/web/my_env/lib/python3.5/site-packages/elasticsearch/client/__init__.py", line 636, in search
    doc_type, '_search'), params=params, body=body)
  File "/home/web/my_env/lib/python3.5/site-packages/elasticsearch/transport.py", line 314, in perform_request
    status, headers, data = connection.perform_request(method, url, params, body, headers=headers, ignore=ignore, timeout=timeout)
  File "/home/web/my_env/lib/python3.5/site-packages/elasticsearch/connection/http_urllib3.py", line 161, in perform_request
    self._raise_error(response.status, raw_data)
  File "/home/web/my_env/lib/python3.5/site-packages/elasticsearch/connection/base.py", line 125, in _raise_error
    raise HTTP_EXCEPTIONS.get(status_code, TransportError)(status_code, error_message, additional_info)
elasticsearch.exceptions.NotFoundError: TransportError(404, 'index_not_found_exception', 'no such index')
2018-03-26 09:18:45,629 security_module.py[line:1288] ERROR elasticsearch Error:
Traceback (most recent call last):
  File "/home/web/my_env/projects/sq_platform/api/user/security_module.py", line 1280, in query_report2
    res = es.search(index=prefix, doc_type="daily_report", body=filter_dict)
  File "/home/web/my_env/lib/python3.5/site-packages/elasticsearch/client/utils.py", line 76, in _wrapped
    return func(*args, params=params, **kwargs)
  File "/home/web/my_env/lib/python3.5/site-packages/elasticsearch/client/__init__.py", line 636, in search
    doc_type, '_search'), params=params, body=body)
  File "/home/web/my_env/lib/python3.5/site-packages/elasticsearch/transport.py", line 314, in perform_request
    status, headers, data = connection.perform_request(method, url, params, body, headers=headers, ignore=ignore, timeout=timeout)
  File "/home/web/my_env/lib/python3.5/site-packages/elasticsearch/connection/http_urllib3.py", line 161, in perform_request
    self._raise_error(response.status, raw_data)
  File "/home/web/my_env/lib/python3.5/site-packages/elasticsearch/connection/base.py", line 125, in _raise_error
    raise HTTP_EXCEPTIONS.get(status_code, TransportError)(status_code, error_message, additional_info)
elasticsearch.exceptions.NotFoundError: TransportError(404, 'index_not_found_exception', 'no such index')
2018-03-26 09:18:49,621 user_view.py[line:313] ERROR Error! 
Traceback (most recent call last):
  File "/home/web/my_env/projects/sq_platform/api/user/user_view.py", line 235, in update_image
    file = upload_files[key]
  File "/home/web/my_env/lib/python3.5/site-packages/flask/debughelpers.py", line 83, in __getitem__
    return oldcls.__getitem__(self, key)
  File "/home/web/my_env/lib/python3.5/site-packages/werkzeug/datastructures.py", line 428, in __getitem__
    raise exceptions.BadRequestKeyError(key)
werkzeug.exceptions.HTTPException.wrap.<locals>.newcls: 400 Bad Request: The browser (or proxy) sent a request that this server could not understand.
2018-03-26 09:24:51,663 security_module.py[line:1288] ERROR elasticsearch Error:
Traceback (most recent call last):
  File "/home/web/my_env/projects/sq_platform/api/user/security_module.py", line 1280, in query_report2
    res = es.search(index=prefix, doc_type="daily_report", body=filter_dict)
  File "/home/web/my_env/lib/python3.5/site-packages/elasticsearch/client/utils.py", line 76, in _wrapped
    return func(*args, params=params, **kwargs)
  File "/home/web/my_env/lib/python3.5/site-packages/elasticsearch/client/__init__.py", line 636, in search
    doc_type, '_search'), params=params, body=body)
  File "/home/web/my_env/lib/python3.5/site-packages/elasticsearch/transport.py", line 314, in perform_request
    status, headers, data = connection.perform_request(method, url, params, body, headers=headers, ignore=ignore, timeout=timeout)
  File "/home/web/my_env/lib/python3.5/site-packages/elasticsearch/connection/http_urllib3.py", line 161, in perform_request
    self._raise_error(response.status, raw_data)
  File "/home/web/my_env/lib/python3.5/site-packages/elasticsearch/connection/base.py", line 125, in _raise_error
    raise HTTP_EXCEPTIONS.get(status_code, TransportError)(status_code, error_message, additional_info)
elasticsearch.exceptions.NotFoundError: TransportError(404, 'index_not_found_exception', 'no such index')
2018-03-26 12:19:27,955 security_module.py[line:1288] ERROR elasticsearch Error:
Traceback (most recent call last):
  File "/home/web/my_env/projects/sq_platform/api/user/security_module.py", line 1280, in query_report2
    res = es.search(index=prefix, doc_type="daily_report", body=filter_dict)
  File "/home/web/my_env/lib/python3.5/site-packages/elasticsearch/client/utils.py", line 76, in _wrapped
    return func(*args, params=params, **kwargs)
  File "/home/web/my_env/lib/python3.5/site-packages/elasticsearch/client/__init__.py", line 636, in search
    doc_type, '_search'), params=params, body=body)
  File "/home/web/my_env/lib/python3.5/site-packages/elasticsearch/transport.py", line 314, in perform_request
    status, headers, data = connection.perform_request(method, url, params, body, headers=headers, ignore=ignore, timeout=timeout)
  File "/home/web/my_env/lib/python3.5/site-packages/elasticsearch/connection/http_urllib3.py", line 161, in perform_request
    self._raise_error(response.status, raw_data)
  File "/home/web/my_env/lib/python3.5/site-packages/elasticsearch/connection/base.py", line 125, in _raise_error
    raise HTTP_EXCEPTIONS.get(status_code, TransportError)(status_code, error_message, additional_info)
elasticsearch.exceptions.NotFoundError: TransportError(404, 'index_not_found_exception', 'no such index')
2018-03-26 12:19:49,168 security_module.py[line:1288] ERROR elasticsearch Error:
Traceback (most recent call last):
  File "/home/web/my_env/projects/sq_platform/api/user/security_module.py", line 1280, in query_report2
    res = es.search(index=prefix, doc_type="daily_report", body=filter_dict)
  File "/home/web/my_env/lib/python3.5/site-packages/elasticsearch/client/utils.py", line 76, in _wrapped
    return func(*args, params=params, **kwargs)
  File "/home/web/my_env/lib/python3.5/site-packages/elasticsearch/client/__init__.py", line 636, in search
    doc_type, '_search'), params=params, body=body)
  File "/home/web/my_env/lib/python3.5/site-packages/elasticsearch/transport.py", line 314, in perform_request
    status, headers, data = connection.perform_request(method, url, params, body, headers=headers, ignore=ignore, timeout=timeout)
  File "/home/web/my_env/lib/python3.5/site-packages/elasticsearch/connection/http_urllib3.py", line 161, in perform_request
    self._raise_error(response.status, raw_data)
  File "/home/web/my_env/lib/python3.5/site-packages/elasticsearch/connection/base.py", line 125, in _raise_error
    raise HTTP_EXCEPTIONS.get(status_code, TransportError)(status_code, error_message, additional_info)
elasticsearch.exceptions.NotFoundError: TransportError(404, 'index_not_found_exception', 'no such index')
2018-03-26 12:19:52,489 security_module.py[line:1288] ERROR elasticsearch Error:
Traceback (most recent call last):
  File "/home/web/my_env/projects/sq_platform/api/user/security_module.py", line 1280, in query_report2
    res = es.search(index=prefix, doc_type="daily_report", body=filter_dict)
  File "/home/web/my_env/lib/python3.5/site-packages/elasticsearch/client/utils.py", line 76, in _wrapped
    return func(*args, params=params, **kwargs)
  File "/home/web/my_env/lib/python3.5/site-packages/elasticsearch/client/__init__.py", line 636, in search
    doc_type, '_search'), params=params, body=body)
  File "/home/web/my_env/lib/python3.5/site-packages/elasticsearch/transport.py", line 314, in perform_request
    status, headers, data = connection.perform_request(method, url, params, body, headers=headers, ignore=ignore, timeout=timeout)
  File "/home/web/my_env/lib/python3.5/site-packages/elasticsearch/connection/http_urllib3.py", line 161, in perform_request
    self._raise_error(response.status, raw_data)
  File "/home/web/my_env/lib/python3.5/site-packages/elasticsearch/connection/base.py", line 125, in _raise_error
    raise HTTP_EXCEPTIONS.get(status_code, TransportError)(status_code, error_message, additional_info)
elasticsearch.exceptions.NotFoundError: TransportError(404, 'index_not_found_exception', 'no such index')
2018-03-26 12:19:56,103 security_module.py[line:1288] ERROR elasticsearch Error:
Traceback (most recent call last):
  File "/home/web/my_env/projects/sq_platform/api/user/security_module.py", line 1280, in query_report2
    res = es.search(index=prefix, doc_type="daily_report", body=filter_dict)
  File "/home/web/my_env/lib/python3.5/site-packages/elasticsearch/client/utils.py", line 76, in _wrapped
    return func(*args, params=params, **kwargs)
  File "/home/web/my_env/lib/python3.5/site-packages/elasticsearch/client/__init__.py", line 636, in search
    doc_type, '_search'), params=params, body=body)
  File "/home/web/my_env/lib/python3.5/site-packages/elasticsearch/transport.py", line 314, in perform_request
    status, headers, data = connection.perform_request(method, url, params, body, headers=headers, ignore=ignore, timeout=timeout)
  File "/home/web/my_env/lib/python3.5/site-packages/elasticsearch/connection/http_urllib3.py", line 161, in perform_request
    self._raise_error(response.status, raw_data)
  File "/home/web/my_env/lib/python3.5/site-packages/elasticsearch/connection/base.py", line 125, in _raise_error
    raise HTTP_EXCEPTIONS.get(status_code, TransportError)(status_code, error_message, additional_info)
elasticsearch.exceptions.NotFoundError: TransportError(404, 'index_not_found_exception', 'no such index')
2018-03-26 12:20:03,608 security_module.py[line:1288] ERROR elasticsearch Error:
Traceback (most recent call last):
  File "/home/web/my_env/projects/sq_platform/api/user/security_module.py", line 1280, in query_report2
    res = es.search(index=prefix, doc_type="daily_report", body=filter_dict)
  File "/home/web/my_env/lib/python3.5/site-packages/elasticsearch/client/utils.py", line 76, in _wrapped
    return func(*args, params=params, **kwargs)
  File "/home/web/my_env/lib/python3.5/site-packages/elasticsearch/client/__init__.py", line 636, in search
    doc_type, '_search'), params=params, body=body)
  File "/home/web/my_env/lib/python3.5/site-packages/elasticsearch/transport.py", line 314, in perform_request
    status, headers, data = connection.perform_request(method, url, params, body, headers=headers, ignore=ignore, timeout=timeout)
  File "/home/web/my_env/lib/python3.5/site-packages/elasticsearch/connection/http_urllib3.py", line 161, in perform_request
    self._raise_error(response.status, raw_data)
  File "/home/web/my_env/lib/python3.5/site-packages/elasticsearch/connection/base.py", line 125, in _raise_error
    raise HTTP_EXCEPTIONS.get(status_code, TransportError)(status_code, error_message, additional_info)
elasticsearch.exceptions.NotFoundError: TransportError(404, 'index_not_found_exception', 'no such index')
2018-03-26 12:20:35,105 security_module.py[line:1288] ERROR elasticsearch Error:
Traceback (most recent call last):
  File "/home/web/my_env/projects/sq_platform/api/user/security_module.py", line 1280, in query_report2
    res = es.search(index=prefix, doc_type="daily_report", body=filter_dict)
  File "/home/web/my_env/lib/python3.5/site-packages/elasticsearch/client/utils.py", line 76, in _wrapped
    return func(*args, params=params, **kwargs)
  File "/home/web/my_env/lib/python3.5/site-packages/elasticsearch/client/__init__.py", line 636, in search
    doc_type, '_search'), params=params, body=body)
  File "/home/web/my_env/lib/python3.5/site-packages/elasticsearch/transport.py", line 314, in perform_request
    status, headers, data = connection.perform_request(method, url, params, body, headers=headers, ignore=ignore, timeout=timeout)
  File "/home/web/my_env/lib/python3.5/site-packages/elasticsearch/connection/http_urllib3.py", line 161, in perform_request
    self._raise_error(response.status, raw_data)
  File "/home/web/my_env/lib/python3.5/site-packages/elasticsearch/connection/base.py", line 125, in _raise_error
    raise HTTP_EXCEPTIONS.get(status_code, TransportError)(status_code, error_message, additional_info)
elasticsearch.exceptions.NotFoundError: TransportError(404, 'index_not_found_exception', 'no such index')
2018-03-26 12:20:55,848 security_module.py[line:1288] ERROR elasticsearch Error:
Traceback (most recent call last):
  File "/home/web/my_env/projects/sq_platform/api/user/security_module.py", line 1280, in query_report2
    res = es.search(index=prefix, doc_type="daily_report", body=filter_dict)
  File "/home/web/my_env/lib/python3.5/site-packages/elasticsearch/client/utils.py", line 76, in _wrapped
    return func(*args, params=params, **kwargs)
  File "/home/web/my_env/lib/python3.5/site-packages/elasticsearch/client/__init__.py", line 636, in search
    doc_type, '_search'), params=params, body=body)
  File "/home/web/my_env/lib/python3.5/site-packages/elasticsearch/transport.py", line 314, in perform_request
    status, headers, data = connection.perform_request(method, url, params, body, headers=headers, ignore=ignore, timeout=timeout)
  File "/home/web/my_env/lib/python3.5/site-packages/elasticsearch/connection/http_urllib3.py", line 161, in perform_request
    self._raise_error(response.status, raw_data)
  File "/home/web/my_env/lib/python3.5/site-packages/elasticsearch/connection/base.py", line 125, in _raise_error
    raise HTTP_EXCEPTIONS.get(status_code, TransportError)(status_code, error_message, additional_info)
elasticsearch.exceptions.NotFoundError: TransportError(404, 'index_not_found_exception', 'no such index')
2018-03-26 12:26:36,515 security_module.py[line:1288] ERROR elasticsearch Error:
Traceback (most recent call last):
  File "/home/web/my_env/projects/sq_platform/api/user/security_module.py", line 1280, in query_report2
    res = es.search(index=prefix, doc_type="daily_report", body=filter_dict)
  File "/home/web/my_env/lib/python3.5/site-packages/elasticsearch/client/utils.py", line 76, in _wrapped
    return func(*args, params=params, **kwargs)
  File "/home/web/my_env/lib/python3.5/site-packages/elasticsearch/client/__init__.py", line 636, in search
    doc_type, '_search'), params=params, body=body)
  File "/home/web/my_env/lib/python3.5/site-packages/elasticsearch/transport.py", line 314, in perform_request
    status, headers, data = connection.perform_request(method, url, params, body, headers=headers, ignore=ignore, timeout=timeout)
  File "/home/web/my_env/lib/python3.5/site-packages/elasticsearch/connection/http_urllib3.py", line 161, in perform_request
    self._raise_error(response.status, raw_data)
  File "/home/web/my_env/lib/python3.5/site-packages/elasticsearch/connection/base.py", line 125, in _raise_error
    raise HTTP_EXCEPTIONS.get(status_code, TransportError)(status_code, error_message, additional_info)
elasticsearch.exceptions.NotFoundError: TransportError(404, 'index_not_found_exception', 'no such index')
2018-03-26 12:27:06,407 security_module.py[line:1288] ERROR elasticsearch Error:
Traceback (most recent call last):
  File "/home/web/my_env/projects/sq_platform/api/user/security_module.py", line 1280, in query_report2
    res = es.search(index=prefix, doc_type="daily_report", body=filter_dict)
  File "/home/web/my_env/lib/python3.5/site-packages/elasticsearch/client/utils.py", line 76, in _wrapped
    return func(*args, params=params, **kwargs)
  File "/home/web/my_env/lib/python3.5/site-packages/elasticsearch/client/__init__.py", line 636, in search
    doc_type, '_search'), params=params, body=body)
  File "/home/web/my_env/lib/python3.5/site-packages/elasticsearch/transport.py", line 314, in perform_request
    status, headers, data = connection.perform_request(method, url, params, body, headers=headers, ignore=ignore, timeout=timeout)
  File "/home/web/my_env/lib/python3.5/site-packages/elasticsearch/connection/http_urllib3.py", line 161, in perform_request
    self._raise_error(response.status, raw_data)
  File "/home/web/my_env/lib/python3.5/site-packages/elasticsearch/connection/base.py", line 125, in _raise_error
    raise HTTP_EXCEPTIONS.get(status_code, TransportError)(status_code, error_message, additional_info)
elasticsearch.exceptions.NotFoundError: TransportError(404, 'index_not_found_exception', 'no such index')
2018-03-26 12:29:07,983 security_module.py[line:1288] ERROR elasticsearch Error:
Traceback (most recent call last):
  File "/home/web/my_env/projects/sq_platform/api/user/security_module.py", line 1280, in query_report2
    res = es.search(index=prefix, doc_type="daily_report", body=filter_dict)
  File "/home/web/my_env/lib/python3.5/site-packages/elasticsearch/client/utils.py", line 76, in _wrapped
    return func(*args, params=params, **kwargs)
  File "/home/web/my_env/lib/python3.5/site-packages/elasticsearch/client/__init__.py", line 636, in search
    doc_type, '_search'), params=params, body=body)
  File "/home/web/my_env/lib/python3.5/site-packages/elasticsearch/transport.py", line 314, in perform_request
    status, headers, data = connection.perform_request(method, url, params, body, headers=headers, ignore=ignore, timeout=timeout)
  File "/home/web/my_env/lib/python3.5/site-packages/elasticsearch/connection/http_urllib3.py", line 161, in perform_request
    self._raise_error(response.status, raw_data)
  File "/home/web/my_env/lib/python3.5/site-packages/elasticsearch/connection/base.py", line 125, in _raise_error
    raise HTTP_EXCEPTIONS.get(status_code, TransportError)(status_code, error_message, additional_info)
elasticsearch.exceptions.NotFoundError: TransportError(404, 'index_not_found_exception', 'no such index')
2018-03-26 12:29:07,985 security_module.py[line:1288] ERROR elasticsearch Error:
Traceback (most recent call last):
  File "/home/web/my_env/projects/sq_platform/api/user/security_module.py", line 1280, in query_report2
    res = es.search(index=prefix, doc_type="daily_report", body=filter_dict)
  File "/home/web/my_env/lib/python3.5/site-packages/elasticsearch/client/utils.py", line 76, in _wrapped
    return func(*args, params=params, **kwargs)
  File "/home/web/my_env/lib/python3.5/site-packages/elasticsearch/client/__init__.py", line 636, in search
    doc_type, '_search'), params=params, body=body)
  File "/home/web/my_env/lib/python3.5/site-packages/elasticsearch/transport.py", line 314, in perform_request
    status, headers, data = connection.perform_request(method, url, params, body, headers=headers, ignore=ignore, timeout=timeout)
  File "/home/web/my_env/lib/python3.5/site-packages/elasticsearch/connection/http_urllib3.py", line 161, in perform_request
    self._raise_error(response.status, raw_data)
  File "/home/web/my_env/lib/python3.5/site-packages/elasticsearch/connection/base.py", line 125, in _raise_error
    raise HTTP_EXCEPTIONS.get(status_code, TransportError)(status_code, error_message, additional_info)
elasticsearch.exceptions.NotFoundError: TransportError(404, 'index_not_found_exception', 'no such index')
2018-03-26 12:39:56,384 security_module.py[line:1288] ERROR elasticsearch Error:
Traceback (most recent call last):
  File "/home/web/my_env/projects/sq_platform/api/user/security_module.py", line 1280, in query_report2
    res = es.search(index=prefix, doc_type="daily_report", body=filter_dict)
  File "/home/web/my_env/lib/python3.5/site-packages/elasticsearch/client/utils.py", line 76, in _wrapped
    return func(*args, params=params, **kwargs)
  File "/home/web/my_env/lib/python3.5/site-packages/elasticsearch/client/__init__.py", line 636, in search
    doc_type, '_search'), params=params, body=body)
  File "/home/web/my_env/lib/python3.5/site-packages/elasticsearch/transport.py", line 314, in perform_request
    status, headers, data = connection.perform_request(method, url, params, body, headers=headers, ignore=ignore, timeout=timeout)
  File "/home/web/my_env/lib/python3.5/site-packages/elasticsearch/connection/http_urllib3.py", line 161, in perform_request
    self._raise_error(response.status, raw_data)
  File "/home/web/my_env/lib/python3.5/site-packages/elasticsearch/connection/base.py", line 125, in _raise_error
    raise HTTP_EXCEPTIONS.get(status_code, TransportError)(status_code, error_message, additional_info)
elasticsearch.exceptions.NotFoundError: TransportError(404, 'index_not_found_exception', 'no such index')
2018-03-26 12:42:00,479 security_module.py[line:1288] ERROR elasticsearch Error:
Traceback (most recent call last):
  File "/home/web/my_env/projects/sq_platform/api/user/security_module.py", line 1280, in query_report2
    res = es.search(index=prefix, doc_type="daily_report", body=filter_dict)
  File "/home/web/my_env/lib/python3.5/site-packages/elasticsearch/client/utils.py", line 76, in _wrapped
    return func(*args, params=params, **kwargs)
  File "/home/web/my_env/lib/python3.5/site-packages/elasticsearch/client/__init__.py", line 636, in search
    doc_type, '_search'), params=params, body=body)
  File "/home/web/my_env/lib/python3.5/site-packages/elasticsearch/transport.py", line 314, in perform_request
    status, headers, data = connection.perform_request(method, url, params, body, headers=headers, ignore=ignore, timeout=timeout)
  File "/home/web/my_env/lib/python3.5/site-packages/elasticsearch/connection/http_urllib3.py", line 161, in perform_request
    self._raise_error(response.status, raw_data)
  File "/home/web/my_env/lib/python3.5/site-packages/elasticsearch/connection/base.py", line 125, in _raise_error
    raise HTTP_EXCEPTIONS.get(status_code, TransportError)(status_code, error_message, additional_info)
elasticsearch.exceptions.NotFoundError: TransportError(404, 'index_not_found_exception', 'no such index')
2018-03-26 12:45:29,037 security_module.py[line:1288] ERROR elasticsearch Error:
Traceback (most recent call last):
  File "/home/web/my_env/projects/sq_platform/api/user/security_module.py", line 1280, in query_report2
    res = es.search(index=prefix, doc_type="daily_report", body=filter_dict)
  File "/home/web/my_env/lib/python3.5/site-packages/elasticsearch/client/utils.py", line 76, in _wrapped
    return func(*args, params=params, **kwargs)
  File "/home/web/my_env/lib/python3.5/site-packages/elasticsearch/client/__init__.py", line 636, in search
    doc_type, '_search'), params=params, body=body)
  File "/home/web/my_env/lib/python3.5/site-packages/elasticsearch/transport.py", line 314, in perform_request
    status, headers, data = connection.perform_request(method, url, params, body, headers=headers, ignore=ignore, timeout=timeout)
  File "/home/web/my_env/lib/python3.5/site-packages/elasticsearch/connection/http_urllib3.py", line 161, in perform_request
    self._raise_error(response.status, raw_data)
  File "/home/web/my_env/lib/python3.5/site-packages/elasticsearch/connection/base.py", line 125, in _raise_error
    raise HTTP_EXCEPTIONS.get(status_code, TransportError)(status_code, error_message, additional_info)
elasticsearch.exceptions.NotFoundError: TransportError(404, 'index_not_found_exception', 'no such index')
2018-03-26 17:05:44,390 security_module.py[line:1288] ERROR elasticsearch Error:
Traceback (most recent call last):
  File "/home/web/my_env/projects/sq_platform/api/user/security_module.py", line 1280, in query_report2
    res = es.search(index=prefix, doc_type="daily_report", body=filter_dict)
  File "/home/web/my_env/lib/python3.5/site-packages/elasticsearch/client/utils.py", line 76, in _wrapped
    return func(*args, params=params, **kwargs)
  File "/home/web/my_env/lib/python3.5/site-packages/elasticsearch/client/__init__.py", line 636, in search
    doc_type, '_search'), params=params, body=body)
  File "/home/web/my_env/lib/python3.5/site-packages/elasticsearch/transport.py", line 314, in perform_request
    status, headers, data = connection.perform_request(method, url, params, body, headers=headers, ignore=ignore, timeout=timeout)
  File "/home/web/my_env/lib/python3.5/site-packages/elasticsearch/connection/http_urllib3.py", line 161, in perform_request
    self._raise_error(response.status, raw_data)
  File "/home/web/my_env/lib/python3.5/site-packages/elasticsearch/connection/base.py", line 125, in _raise_error
    raise HTTP_EXCEPTIONS.get(status_code, TransportError)(status_code, error_message, additional_info)
elasticsearch.exceptions.NotFoundError: TransportError(404, 'index_not_found_exception', 'no such index')
2018-03-26 17:05:45,790 security_module.py[line:1288] ERROR elasticsearch Error:
Traceback (most recent call last):
  File "/home/web/my_env/projects/sq_platform/api/user/security_module.py", line 1280, in query_report2
    res = es.search(index=prefix, doc_type="daily_report", body=filter_dict)
  File "/home/web/my_env/lib/python3.5/site-packages/elasticsearch/client/utils.py", line 76, in _wrapped
    return func(*args, params=params, **kwargs)
  File "/home/web/my_env/lib/python3.5/site-packages/elasticsearch/client/__init__.py", line 636, in search
    doc_type, '_search'), params=params, body=body)
  File "/home/web/my_env/lib/python3.5/site-packages/elasticsearch/transport.py", line 314, in perform_request
    status, headers, data = connection.perform_request(method, url, params, body, headers=headers, ignore=ignore, timeout=timeout)
  File "/home/web/my_env/lib/python3.5/site-packages/elasticsearch/connection/http_urllib3.py", line 161, in perform_request
    self._raise_error(response.status, raw_data)
  File "/home/web/my_env/lib/python3.5/site-packages/elasticsearch/connection/base.py", line 125, in _raise_error
    raise HTTP_EXCEPTIONS.get(status_code, TransportError)(status_code, error_message, additional_info)
elasticsearch.exceptions.NotFoundError: TransportError(404, 'index_not_found_exception', 'no such index')
2018-03-26 17:05:48,147 security_module.py[line:1288] ERROR elasticsearch Error:
Traceback (most recent call last):
  File "/home/web/my_env/projects/sq_platform/api/user/security_module.py", line 1280, in query_report2
    res = es.search(index=prefix, doc_type="daily_report", body=filter_dict)
  File "/home/web/my_env/lib/python3.5/site-packages/elasticsearch/client/utils.py", line 76, in _wrapped
    return func(*args, params=params, **kwargs)
  File "/home/web/my_env/lib/python3.5/site-packages/elasticsearch/client/__init__.py", line 636, in search
    doc_type, '_search'), params=params, body=body)
  File "/home/web/my_env/lib/python3.5/site-packages/elasticsearch/transport.py", line 314, in perform_request
    status, headers, data = connection.perform_request(method, url, params, body, headers=headers, ignore=ignore, timeout=timeout)
  File "/home/web/my_env/lib/python3.5/site-packages/elasticsearch/connection/http_urllib3.py", line 161, in perform_request
    self._raise_error(response.status, raw_data)
  File "/home/web/my_env/lib/python3.5/site-packages/elasticsearch/connection/base.py", line 125, in _raise_error
    raise HTTP_EXCEPTIONS.get(status_code, TransportError)(status_code, error_message, additional_info)
elasticsearch.exceptions.NotFoundError: TransportError(404, 'index_not_found_exception', 'no such index')
2018-03-26 17:05:57,837 security_module.py[line:1288] ERROR elasticsearch Error:
Traceback (most recent call last):
  File "/home/web/my_env/projects/sq_platform/api/user/security_module.py", line 1280, in query_report2
    res = es.search(index=prefix, doc_type="daily_report", body=filter_dict)
  File "/home/web/my_env/lib/python3.5/site-packages/elasticsearch/client/utils.py", line 76, in _wrapped
    return func(*args, params=params, **kwargs)
  File "/home/web/my_env/lib/python3.5/site-packages/elasticsearch/client/__init__.py", line 636, in search
    doc_type, '_search'), params=params, body=body)
  File "/home/web/my_env/lib/python3.5/site-packages/elasticsearch/transport.py", line 314, in perform_request
    status, headers, data = connection.perform_request(method, url, params, body, headers=headers, ignore=ignore, timeout=timeout)
  File "/home/web/my_env/lib/python3.5/site-packages/elasticsearch/connection/http_urllib3.py", line 161, in perform_request
    self._raise_error(response.status, raw_data)
  File "/home/web/my_env/lib/python3.5/site-packages/elasticsearch/connection/base.py", line 125, in _raise_error
    raise HTTP_EXCEPTIONS.get(status_code, TransportError)(status_code, error_message, additional_info)
elasticsearch.exceptions.NotFoundError: TransportError(404, 'index_not_found_exception', 'no such index')
2018-03-26 17:06:02,680 security_module.py[line:1288] ERROR elasticsearch Error:
Traceback (most recent call last):
  File "/home/web/my_env/projects/sq_platform/api/user/security_module.py", line 1280, in query_report2
    res = es.search(index=prefix, doc_type="daily_report", body=filter_dict)
  File "/home/web/my_env/lib/python3.5/site-packages/elasticsearch/client/utils.py", line 76, in _wrapped
    return func(*args, params=params, **kwargs)
  File "/home/web/my_env/lib/python3.5/site-packages/elasticsearch/client/__init__.py", line 636, in search
    doc_type, '_search'), params=params, body=body)
  File "/home/web/my_env/lib/python3.5/site-packages/elasticsearch/transport.py", line 314, in perform_request
    status, headers, data = connection.perform_request(method, url, params, body, headers=headers, ignore=ignore, timeout=timeout)
  File "/home/web/my_env/lib/python3.5/site-packages/elasticsearch/connection/http_urllib3.py", line 161, in perform_request
    self._raise_error(response.status, raw_data)
  File "/home/web/my_env/lib/python3.5/site-packages/elasticsearch/connection/base.py", line 125, in _raise_error
    raise HTTP_EXCEPTIONS.get(status_code, TransportError)(status_code, error_message, additional_info)
elasticsearch.exceptions.NotFoundError: TransportError(404, 'index_not_found_exception', 'no such index')
2018-03-26 17:06:04,207 security_module.py[line:1288] ERROR elasticsearch Error:
Traceback (most recent call last):
  File "/home/web/my_env/projects/sq_platform/api/user/security_module.py", line 1280, in query_report2
    res = es.search(index=prefix, doc_type="daily_report", body=filter_dict)
  File "/home/web/my_env/lib/python3.5/site-packages/elasticsearch/client/utils.py", line 76, in _wrapped
    return func(*args, params=params, **kwargs)
  File "/home/web/my_env/lib/python3.5/site-packages/elasticsearch/client/__init__.py", line 636, in search
    doc_type, '_search'), params=params, body=body)
  File "/home/web/my_env/lib/python3.5/site-packages/elasticsearch/transport.py", line 314, in perform_request
    status, headers, data = connection.perform_request(method, url, params, body, headers=headers, ignore=ignore, timeout=timeout)
  File "/home/web/my_env/lib/python3.5/site-packages/elasticsearch/connection/http_urllib3.py", line 161, in perform_request
    self._raise_error(response.status, raw_data)
  File "/home/web/my_env/lib/python3.5/site-packages/elasticsearch/connection/base.py", line 125, in _raise_error
    raise HTTP_EXCEPTIONS.get(status_code, TransportError)(status_code, error_message, additional_info)
elasticsearch.exceptions.NotFoundError: TransportError(404, 'index_not_found_exception', 'no such index')
2018-03-26 17:09:59,733 security_module.py[line:1288] ERROR elasticsearch Error:
Traceback (most recent call last):
  File "/home/web/my_env/projects/sq_platform/api/user/security_module.py", line 1280, in query_report2
    res = es.search(index=prefix, doc_type="daily_report", body=filter_dict)
  File "/home/web/my_env/lib/python3.5/site-packages/elasticsearch/client/utils.py", line 76, in _wrapped
    return func(*args, params=params, **kwargs)
  File "/home/web/my_env/lib/python3.5/site-packages/elasticsearch/client/__init__.py", line 636, in search
    doc_type, '_search'), params=params, body=body)
  File "/home/web/my_env/lib/python3.5/site-packages/elasticsearch/transport.py", line 314, in perform_request
    status, headers, data = connection.perform_request(method, url, params, body, headers=headers, ignore=ignore, timeout=timeout)
  File "/home/web/my_env/lib/python3.5/site-packages/elasticsearch/connection/http_urllib3.py", line 161, in perform_request
    self._raise_error(response.status, raw_data)
  File "/home/web/my_env/lib/python3.5/site-packages/elasticsearch/connection/base.py", line 125, in _raise_error
    raise HTTP_EXCEPTIONS.get(status_code, TransportError)(status_code, error_message, additional_info)
elasticsearch.exceptions.NotFoundError: TransportError(404, 'index_not_found_exception', 'no such index')
2018-03-26 17:45:44,855 security_module.py[line:1297] ERROR elasticsearch Error:
Traceback (most recent call last):
  File "/home/web/my_env/projects/sq_platform/api/user/security_module.py", line 1280, in query_report2
    res = es.search(index=prefix, doc_type="daily_report", body=filter_dict)
  File "/home/web/my_env/lib/python3.5/site-packages/elasticsearch/client/utils.py", line 76, in _wrapped
    return func(*args, params=params, **kwargs)
  File "/home/web/my_env/lib/python3.5/site-packages/elasticsearch/client/__init__.py", line 636, in search
    doc_type, '_search'), params=params, body=body)
  File "/home/web/my_env/lib/python3.5/site-packages/elasticsearch/transport.py", line 314, in perform_request
    status, headers, data = connection.perform_request(method, url, params, body, headers=headers, ignore=ignore, timeout=timeout)
  File "/home/web/my_env/lib/python3.5/site-packages/elasticsearch/connection/http_urllib3.py", line 161, in perform_request
    self._raise_error(response.status, raw_data)
  File "/home/web/my_env/lib/python3.5/site-packages/elasticsearch/connection/base.py", line 125, in _raise_error
    raise HTTP_EXCEPTIONS.get(status_code, TransportError)(status_code, error_message, additional_info)
elasticsearch.exceptions.AuthorizationException: TransportError(403, 'security_exception', 'action [indices:data/read/search] is unauthorized for user [safego]')
2018-03-26 18:05:48,498 security_module.py[line:1297] ERROR elasticsearch Error:
Traceback (most recent call last):
  File "/home/web/my_env/projects/sq_platform/api/user/security_module.py", line 1280, in query_report2
    res = es.search(index=prefix, doc_type="daily_report", body=filter_dict)
  File "/home/web/my_env/lib/python3.5/site-packages/elasticsearch/client/utils.py", line 76, in _wrapped
    return func(*args, params=params, **kwargs)
  File "/home/web/my_env/lib/python3.5/site-packages/elasticsearch/client/__init__.py", line 636, in search
    doc_type, '_search'), params=params, body=body)
  File "/home/web/my_env/lib/python3.5/site-packages/elasticsearch/transport.py", line 314, in perform_request
    status, headers, data = connection.perform_request(method, url, params, body, headers=headers, ignore=ignore, timeout=timeout)
  File "/home/web/my_env/lib/python3.5/site-packages/elasticsearch/connection/http_urllib3.py", line 161, in perform_request
    self._raise_error(response.status, raw_data)
  File "/home/web/my_env/lib/python3.5/site-packages/elasticsearch/connection/base.py", line 125, in _raise_error
    raise HTTP_EXCEPTIONS.get(status_code, TransportError)(status_code, error_message, additional_info)
elasticsearch.exceptions.AuthorizationException: TransportError(403, 'security_exception', 'action [indices:data/read/search] is unauthorized for user [safego]')
2018-03-26 18:11:42,032 security_module.py[line:1297] ERROR elasticsearch Error:
Traceback (most recent call last):
  File "/home/web/my_env/projects/sq_platform/api/user/security_module.py", line 1280, in query_report2
    res = es.search(index=prefix, doc_type="daily_report", body=filter_dict)
  File "/home/web/my_env/lib/python3.5/site-packages/elasticsearch/client/utils.py", line 76, in _wrapped
    return func(*args, params=params, **kwargs)
  File "/home/web/my_env/lib/python3.5/site-packages/elasticsearch/client/__init__.py", line 636, in search
    doc_type, '_search'), params=params, body=body)
  File "/home/web/my_env/lib/python3.5/site-packages/elasticsearch/transport.py", line 314, in perform_request
    status, headers, data = connection.perform_request(method, url, params, body, headers=headers, ignore=ignore, timeout=timeout)
  File "/home/web/my_env/lib/python3.5/site-packages/elasticsearch/connection/http_urllib3.py", line 161, in perform_request
    self._raise_error(response.status, raw_data)
  File "/home/web/my_env/lib/python3.5/site-packages/elasticsearch/connection/base.py", line 125, in _raise_error
    raise HTTP_EXCEPTIONS.get(status_code, TransportError)(status_code, error_message, additional_info)
elasticsearch.exceptions.AuthorizationException: TransportError(403, 'security_exception', 'action [indices:data/read/search] is unauthorized for user [safego]')
2018-03-26 19:38:35,526 security_module.py[line:1288] ERROR elasticsearch Error:
Traceback (most recent call last):
  File "/home/web/my_env/projects/sq_platform/api/user/security_module.py", line 1280, in query_report2
    res = es.search(index=prefix, doc_type="daily_report", body=filter_dict)
  File "/home/web/my_env/lib/python3.5/site-packages/elasticsearch/client/utils.py", line 76, in _wrapped
    return func(*args, params=params, **kwargs)
  File "/home/web/my_env/lib/python3.5/site-packages/elasticsearch/client/__init__.py", line 636, in search
    doc_type, '_search'), params=params, body=body)
  File "/home/web/my_env/lib/python3.5/site-packages/elasticsearch/transport.py", line 314, in perform_request
    status, headers, data = connection.perform_request(method, url, params, body, headers=headers, ignore=ignore, timeout=timeout)
  File "/home/web/my_env/lib/python3.5/site-packages/elasticsearch/connection/http_urllib3.py", line 161, in perform_request
    self._raise_error(response.status, raw_data)
  File "/home/web/my_env/lib/python3.5/site-packages/elasticsearch/connection/base.py", line 125, in _raise_error
    raise HTTP_EXCEPTIONS.get(status_code, TransportError)(status_code, error_message, additional_info)
elasticsearch.exceptions.NotFoundError: TransportError(404, 'index_not_found_exception', 'no such index')
2018-03-26 19:42:25,063 security_module.py[line:1288] ERROR elasticsearch Error:
Traceback (most recent call last):
  File "/home/web/my_env/projects/sq_platform/api/user/security_module.py", line 1280, in query_report2
    res = es.search(index=prefix, doc_type="daily_report", body=filter_dict)
  File "/home/web/my_env/lib/python3.5/site-packages/elasticsearch/client/utils.py", line 76, in _wrapped
    return func(*args, params=params, **kwargs)
  File "/home/web/my_env/lib/python3.5/site-packages/elasticsearch/client/__init__.py", line 636, in search
    doc_type, '_search'), params=params, body=body)
  File "/home/web/my_env/lib/python3.5/site-packages/elasticsearch/transport.py", line 314, in perform_request
    status, headers, data = connection.perform_request(method, url, params, body, headers=headers, ignore=ignore, timeout=timeout)
  File "/home/web/my_env/lib/python3.5/site-packages/elasticsearch/connection/http_urllib3.py", line 161, in perform_request
    self._raise_error(response.status, raw_data)
  File "/home/web/my_env/lib/python3.5/site-packages/elasticsearch/connection/base.py", line 125, in _raise_error
    raise HTTP_EXCEPTIONS.get(status_code, TransportError)(status_code, error_message, additional_info)
elasticsearch.exceptions.NotFoundError: TransportError(404, 'index_not_found_exception', 'no such index')
2018-03-26 20:22:26,544 security_module.py[line:1288] ERROR elasticsearch Error:
Traceback (most recent call last):
  File "/home/web/my_env/projects/sq_platform/api/user/security_module.py", line 1280, in query_report2
    res = es.search(index=prefix, doc_type="daily_report", body=filter_dict)
  File "/home/web/my_env/lib/python3.5/site-packages/elasticsearch/client/utils.py", line 76, in _wrapped
    return func(*args, params=params, **kwargs)
  File "/home/web/my_env/lib/python3.5/site-packages/elasticsearch/client/__init__.py", line 636, in search
    doc_type, '_search'), params=params, body=body)
  File "/home/web/my_env/lib/python3.5/site-packages/elasticsearch/transport.py", line 314, in perform_request
    status, headers, data = connection.perform_request(method, url, params, body, headers=headers, ignore=ignore, timeout=timeout)
  File "/home/web/my_env/lib/python3.5/site-packages/elasticsearch/connection/http_urllib3.py", line 161, in perform_request
    self._raise_error(response.status, raw_data)
  File "/home/web/my_env/lib/python3.5/site-packages/elasticsearch/connection/base.py", line 125, in _raise_error
    raise HTTP_EXCEPTIONS.get(status_code, TransportError)(status_code, error_message, additional_info)
elasticsearch.exceptions.NotFoundError: TransportError(404, 'index_not_found_exception', 'no such index')
2018-03-26 20:28:03,826 security_module.py[line:1288] ERROR elasticsearch Error:
Traceback (most recent call last):
  File "/home/web/my_env/projects/sq_platform/api/user/security_module.py", line 1280, in query_report2
    res = es.search(index=prefix, doc_type="daily_report", body=filter_dict)
  File "/home/web/my_env/lib/python3.5/site-packages/elasticsearch/client/utils.py", line 76, in _wrapped
    return func(*args, params=params, **kwargs)
  File "/home/web/my_env/lib/python3.5/site-packages/elasticsearch/client/__init__.py", line 636, in search
    doc_type, '_search'), params=params, body=body)
  File "/home/web/my_env/lib/python3.5/site-packages/elasticsearch/transport.py", line 314, in perform_request
    status, headers, data = connection.perform_request(method, url, params, body, headers=headers, ignore=ignore, timeout=timeout)
  File "/home/web/my_env/lib/python3.5/site-packages/elasticsearch/connection/http_urllib3.py", line 161, in perform_request
    self._raise_error(response.status, raw_data)
  File "/home/web/my_env/lib/python3.5/site-packages/elasticsearch/connection/base.py", line 125, in _raise_error
    raise HTTP_EXCEPTIONS.get(status_code, TransportError)(status_code, error_message, additional_info)
elasticsearch.exceptions.NotFoundError: TransportError(404, 'index_not_found_exception', 'no such index')
2018-03-26 20:29:08,799 security_module.py[line:1288] ERROR elasticsearch Error:
Traceback (most recent call last):
  File "/home/web/my_env/projects/sq_platform/api/user/security_module.py", line 1280, in query_report2
    res = es.search(index=prefix, doc_type="daily_report", body=filter_dict)
  File "/home/web/my_env/lib/python3.5/site-packages/elasticsearch/client/utils.py", line 76, in _wrapped
    return func(*args, params=params, **kwargs)
  File "/home/web/my_env/lib/python3.5/site-packages/elasticsearch/client/__init__.py", line 636, in search
    doc_type, '_search'), params=params, body=body)
  File "/home/web/my_env/lib/python3.5/site-packages/elasticsearch/transport.py", line 314, in perform_request
    status, headers, data = connection.perform_request(method, url, params, body, headers=headers, ignore=ignore, timeout=timeout)
  File "/home/web/my_env/lib/python3.5/site-packages/elasticsearch/connection/http_urllib3.py", line 161, in perform_request
    self._raise_error(response.status, raw_data)
  File "/home/web/my_env/lib/python3.5/site-packages/elasticsearch/connection/base.py", line 125, in _raise_error
    raise HTTP_EXCEPTIONS.get(status_code, TransportError)(status_code, error_message, additional_info)
elasticsearch.exceptions.NotFoundError: TransportError(404, 'index_not_found_exception', 'no such index')
2018-03-26 20:34:13,053 security_module.py[line:1288] ERROR elasticsearch Error:
Traceback (most recent call last):
  File "/home/web/my_env/projects/sq_platform/api/user/security_module.py", line 1280, in query_report2
    res = es.search(index=prefix, doc_type="daily_report", body=filter_dict)
  File "/home/web/my_env/lib/python3.5/site-packages/elasticsearch/client/utils.py", line 76, in _wrapped
    return func(*args, params=params, **kwargs)
  File "/home/web/my_env/lib/python3.5/site-packages/elasticsearch/client/__init__.py", line 636, in search
    doc_type, '_search'), params=params, body=body)
  File "/home/web/my_env/lib/python3.5/site-packages/elasticsearch/transport.py", line 314, in perform_request
    status, headers, data = connection.perform_request(method, url, params, body, headers=headers, ignore=ignore, timeout=timeout)
  File "/home/web/my_env/lib/python3.5/site-packages/elasticsearch/connection/http_urllib3.py", line 161, in perform_request
    self._raise_error(response.status, raw_data)
  File "/home/web/my_env/lib/python3.5/site-packages/elasticsearch/connection/base.py", line 125, in _raise_error
    raise HTTP_EXCEPTIONS.get(status_code, TransportError)(status_code, error_message, additional_info)
elasticsearch.exceptions.NotFoundError: TransportError(404, 'index_not_found_exception', 'no such index')
2018-03-26 20:39:30,594 security_module.py[line:1288] ERROR elasticsearch Error:
Traceback (most recent call last):
  File "/home/web/my_env/projects/sq_platform/api/user/security_module.py", line 1280, in query_report2
    res = es.search(index=prefix, doc_type="daily_report", body=filter_dict)
  File "/home/web/my_env/lib/python3.5/site-packages/elasticsearch/client/utils.py", line 76, in _wrapped
    return func(*args, params=params, **kwargs)
  File "/home/web/my_env/lib/python3.5/site-packages/elasticsearch/client/__init__.py", line 636, in search
    doc_type, '_search'), params=params, body=body)
  File "/home/web/my_env/lib/python3.5/site-packages/elasticsearch/transport.py", line 314, in perform_request
    status, headers, data = connection.perform_request(method, url, params, body, headers=headers, ignore=ignore, timeout=timeout)
  File "/home/web/my_env/lib/python3.5/site-packages/elasticsearch/connection/http_urllib3.py", line 161, in perform_request
    self._raise_error(response.status, raw_data)
  File "/home/web/my_env/lib/python3.5/site-packages/elasticsearch/connection/base.py", line 125, in _raise_error
    raise HTTP_EXCEPTIONS.get(status_code, TransportError)(status_code, error_message, additional_info)
elasticsearch.exceptions.NotFoundError: TransportError(404, 'index_not_found_exception', 'no such index')
2018-03-26 20:43:58,820 security_module.py[line:1288] ERROR elasticsearch Error:
Traceback (most recent call last):
  File "/home/web/my_env/projects/sq_platform/api/user/security_module.py", line 1280, in query_report2
    res = es.search(index=prefix, doc_type="daily_report", body=filter_dict)
  File "/home/web/my_env/lib/python3.5/site-packages/elasticsearch/client/utils.py", line 76, in _wrapped
    return func(*args, params=params, **kwargs)
  File "/home/web/my_env/lib/python3.5/site-packages/elasticsearch/client/__init__.py", line 636, in search
    doc_type, '_search'), params=params, body=body)
  File "/home/web/my_env/lib/python3.5/site-packages/elasticsearch/transport.py", line 314, in perform_request
    status, headers, data = connection.perform_request(method, url, params, body, headers=headers, ignore=ignore, timeout=timeout)
  File "/home/web/my_env/lib/python3.5/site-packages/elasticsearch/connection/http_urllib3.py", line 161, in perform_request
    self._raise_error(response.status, raw_data)
  File "/home/web/my_env/lib/python3.5/site-packages/elasticsearch/connection/base.py", line 125, in _raise_error
    raise HTTP_EXCEPTIONS.get(status_code, TransportError)(status_code, error_message, additional_info)
elasticsearch.exceptions.NotFoundError: TransportError(404, 'index_not_found_exception', 'no such index')
2018-03-26 20:46:40,839 security_module.py[line:1288] ERROR elasticsearch Error:
Traceback (most recent call last):
  File "/home/web/my_env/projects/sq_platform/api/user/security_module.py", line 1280, in query_report2
    res = es.search(index=prefix, doc_type="daily_report", body=filter_dict)
  File "/home/web/my_env/lib/python3.5/site-packages/elasticsearch/client/utils.py", line 76, in _wrapped
    return func(*args, params=params, **kwargs)
  File "/home/web/my_env/lib/python3.5/site-packages/elasticsearch/client/__init__.py", line 636, in search
    doc_type, '_search'), params=params, body=body)
  File "/home/web/my_env/lib/python3.5/site-packages/elasticsearch/transport.py", line 314, in perform_request
    status, headers, data = connection.perform_request(method, url, params, body, headers=headers, ignore=ignore, timeout=timeout)
  File "/home/web/my_env/lib/python3.5/site-packages/elasticsearch/connection/http_urllib3.py", line 161, in perform_request
    self._raise_error(response.status, raw_data)
  File "/home/web/my_env/lib/python3.5/site-packages/elasticsearch/connection/base.py", line 125, in _raise_error
    raise HTTP_EXCEPTIONS.get(status_code, TransportError)(status_code, error_message, additional_info)
elasticsearch.exceptions.NotFoundError: TransportError(404, 'index_not_found_exception', 'no such index')
2018-03-26 20:50:53,795 security_module.py[line:1288] ERROR elasticsearch Error:
Traceback (most recent call last):
  File "/home/web/my_env/projects/sq_platform/api/user/security_module.py", line 1280, in query_report2
    res = es.search(index=prefix, doc_type="daily_report", body=filter_dict)
  File "/home/web/my_env/lib/python3.5/site-packages/elasticsearch/client/utils.py", line 76, in _wrapped
    return func(*args, params=params, **kwargs)
  File "/home/web/my_env/lib/python3.5/site-packages/elasticsearch/client/__init__.py", line 636, in search
    doc_type, '_search'), params=params, body=body)
  File "/home/web/my_env/lib/python3.5/site-packages/elasticsearch/transport.py", line 314, in perform_request
    status, headers, data = connection.perform_request(method, url, params, body, headers=headers, ignore=ignore, timeout=timeout)
  File "/home/web/my_env/lib/python3.5/site-packages/elasticsearch/connection/http_urllib3.py", line 161, in perform_request
    self._raise_error(response.status, raw_data)
  File "/home/web/my_env/lib/python3.5/site-packages/elasticsearch/connection/base.py", line 125, in _raise_error
    raise HTTP_EXCEPTIONS.get(status_code, TransportError)(status_code, error_message, additional_info)
elasticsearch.exceptions.NotFoundError: TransportError(404, 'index_not_found_exception', 'no such index')
2018-03-26 20:53:02,731 security_module.py[line:1288] ERROR elasticsearch Error:
Traceback (most recent call last):
  File "/home/web/my_env/projects/sq_platform/api/user/security_module.py", line 1280, in query_report2
    res = es.search(index=prefix, doc_type="daily_report", body=filter_dict)
  File "/home/web/my_env/lib/python3.5/site-packages/elasticsearch/client/utils.py", line 76, in _wrapped
    return func(*args, params=params, **kwargs)
  File "/home/web/my_env/lib/python3.5/site-packages/elasticsearch/client/__init__.py", line 636, in search
    doc_type, '_search'), params=params, body=body)
  File "/home/web/my_env/lib/python3.5/site-packages/elasticsearch/transport.py", line 314, in perform_request
    status, headers, data = connection.perform_request(method, url, params, body, headers=headers, ignore=ignore, timeout=timeout)
  File "/home/web/my_env/lib/python3.5/site-packages/elasticsearch/connection/http_urllib3.py", line 161, in perform_request
    self._raise_error(response.status, raw_data)
  File "/home/web/my_env/lib/python3.5/site-packages/elasticsearch/connection/base.py", line 125, in _raise_error
    raise HTTP_EXCEPTIONS.get(status_code, TransportError)(status_code, error_message, additional_info)
elasticsearch.exceptions.NotFoundError: TransportError(404, 'index_not_found_exception', 'no such index')
2018-03-26 20:58:42,713 security_module.py[line:1288] ERROR elasticsearch Error:
Traceback (most recent call last):
  File "/home/web/my_env/projects/sq_platform/api/user/security_module.py", line 1280, in query_report2
    res = es.search(index=prefix, doc_type="daily_report", body=filter_dict)
  File "/home/web/my_env/lib/python3.5/site-packages/elasticsearch/client/utils.py", line 76, in _wrapped
    return func(*args, params=params, **kwargs)
  File "/home/web/my_env/lib/python3.5/site-packages/elasticsearch/client/__init__.py", line 636, in search
    doc_type, '_search'), params=params, body=body)
  File "/home/web/my_env/lib/python3.5/site-packages/elasticsearch/transport.py", line 314, in perform_request
    status, headers, data = connection.perform_request(method, url, params, body, headers=headers, ignore=ignore, timeout=timeout)
  File "/home/web/my_env/lib/python3.5/site-packages/elasticsearch/connection/http_urllib3.py", line 161, in perform_request
    self._raise_error(response.status, raw_data)
  File "/home/web/my_env/lib/python3.5/site-packages/elasticsearch/connection/base.py", line 125, in _raise_error
    raise HTTP_EXCEPTIONS.get(status_code, TransportError)(status_code, error_message, additional_info)
elasticsearch.exceptions.NotFoundError: TransportError(404, 'index_not_found_exception', 'no such index')
2018-03-27 10:51:47,076 user_view.py[line:313] ERROR Error! 
Traceback (most recent call last):
  File "/home/web/my_env/projects/sq_platform/api/user/user_view.py", line 235, in update_image
    file = upload_files[key]
  File "/home/web/my_env/lib/python3.5/site-packages/werkzeug/datastructures.py", line 428, in __getitem__
    raise exceptions.BadRequestKeyError(key)
werkzeug.exceptions.HTTPException.wrap.<locals>.newcls: 400 Bad Request: The browser (or proxy) sent a request that this server could not understand.
2018-03-27 10:51:47,302 security_module.py[line:1288] ERROR elasticsearch Error:
Traceback (most recent call last):
  File "/home/web/my_env/projects/sq_platform/api/user/security_module.py", line 1280, in query_report2
    res = es.search(index=prefix, doc_type="daily_report", body=filter_dict)
  File "/home/web/my_env/lib/python3.5/site-packages/elasticsearch/client/utils.py", line 76, in _wrapped
    return func(*args, params=params, **kwargs)
  File "/home/web/my_env/lib/python3.5/site-packages/elasticsearch/client/__init__.py", line 636, in search
    doc_type, '_search'), params=params, body=body)
  File "/home/web/my_env/lib/python3.5/site-packages/elasticsearch/transport.py", line 314, in perform_request
    status, headers, data = connection.perform_request(method, url, params, body, headers=headers, ignore=ignore, timeout=timeout)
  File "/home/web/my_env/lib/python3.5/site-packages/elasticsearch/connection/http_urllib3.py", line 161, in perform_request
    self._raise_error(response.status, raw_data)
  File "/home/web/my_env/lib/python3.5/site-packages/elasticsearch/connection/base.py", line 125, in _raise_error
    raise HTTP_EXCEPTIONS.get(status_code, TransportError)(status_code, error_message, additional_info)
elasticsearch.exceptions.NotFoundError: TransportError(404, 'index_not_found_exception', 'no such index')
2018-03-27 10:51:54,687 security_module.py[line:1288] ERROR elasticsearch Error:
Traceback (most recent call last):
  File "/home/web/my_env/projects/sq_platform/api/user/security_module.py", line 1280, in query_report2
    res = es.search(index=prefix, doc_type="daily_report", body=filter_dict)
  File "/home/web/my_env/lib/python3.5/site-packages/elasticsearch/client/utils.py", line 76, in _wrapped
    return func(*args, params=params, **kwargs)
  File "/home/web/my_env/lib/python3.5/site-packages/elasticsearch/client/__init__.py", line 636, in search
    doc_type, '_search'), params=params, body=body)
  File "/home/web/my_env/lib/python3.5/site-packages/elasticsearch/transport.py", line 314, in perform_request
    status, headers, data = connection.perform_request(method, url, params, body, headers=headers, ignore=ignore, timeout=timeout)
  File "/home/web/my_env/lib/python3.5/site-packages/elasticsearch/connection/http_urllib3.py", line 161, in perform_request
    self._raise_error(response.status, raw_data)
  File "/home/web/my_env/lib/python3.5/site-packages/elasticsearch/connection/base.py", line 125, in _raise_error
    raise HTTP_EXCEPTIONS.get(status_code, TransportError)(status_code, error_message, additional_info)
elasticsearch.exceptions.NotFoundError: TransportError(404, 'index_not_found_exception', 'no such index')
2018-03-27 11:31:13,558 security_module.py[line:1288] ERROR elasticsearch Error:
Traceback (most recent call last):
  File "/home/web/my_env/projects/sq_platform/api/user/security_module.py", line 1280, in query_report2
    res = es.search(index=prefix, doc_type="daily_report", body=filter_dict)
  File "/home/web/my_env/lib/python3.5/site-packages/elasticsearch/client/utils.py", line 76, in _wrapped
    return func(*args, params=params, **kwargs)
  File "/home/web/my_env/lib/python3.5/site-packages/elasticsearch/client/__init__.py", line 636, in search
    doc_type, '_search'), params=params, body=body)
  File "/home/web/my_env/lib/python3.5/site-packages/elasticsearch/transport.py", line 314, in perform_request
    status, headers, data = connection.perform_request(method, url, params, body, headers=headers, ignore=ignore, timeout=timeout)
  File "/home/web/my_env/lib/python3.5/site-packages/elasticsearch/connection/http_urllib3.py", line 161, in perform_request
    self._raise_error(response.status, raw_data)
  File "/home/web/my_env/lib/python3.5/site-packages/elasticsearch/connection/base.py", line 125, in _raise_error
    raise HTTP_EXCEPTIONS.get(status_code, TransportError)(status_code, error_message, additional_info)
elasticsearch.exceptions.NotFoundError: TransportError(404, 'index_not_found_exception', 'no such index')
2018-03-27 11:43:34,837 security_module.py[line:1288] ERROR elasticsearch Error:
Traceback (most recent call last):
  File "/home/web/my_env/projects/sq_platform/api/user/security_module.py", line 1280, in query_report2
    res = es.search(index=prefix, doc_type="daily_report", body=filter_dict)
  File "/home/web/my_env/lib/python3.5/site-packages/elasticsearch/client/utils.py", line 76, in _wrapped
    return func(*args, params=params, **kwargs)
  File "/home/web/my_env/lib/python3.5/site-packages/elasticsearch/client/__init__.py", line 636, in search
    doc_type, '_search'), params=params, body=body)
  File "/home/web/my_env/lib/python3.5/site-packages/elasticsearch/transport.py", line 314, in perform_request
    status, headers, data = connection.perform_request(method, url, params, body, headers=headers, ignore=ignore, timeout=timeout)
  File "/home/web/my_env/lib/python3.5/site-packages/elasticsearch/connection/http_urllib3.py", line 161, in perform_request
    self._raise_error(response.status, raw_data)
  File "/home/web/my_env/lib/python3.5/site-packages/elasticsearch/connection/base.py", line 125, in _raise_error
    raise HTTP_EXCEPTIONS.get(status_code, TransportError)(status_code, error_message, additional_info)
elasticsearch.exceptions.NotFoundError: TransportError(404, 'index_not_found_exception', 'no such index')
2018-03-27 11:43:54,580 security_module.py[line:1288] ERROR elasticsearch Error:
Traceback (most recent call last):
  File "/home/web/my_env/projects/sq_platform/api/user/security_module.py", line 1280, in query_report2
    res = es.search(index=prefix, doc_type="daily_report", body=filter_dict)
  File "/home/web/my_env/lib/python3.5/site-packages/elasticsearch/client/utils.py", line 76, in _wrapped
    return func(*args, params=params, **kwargs)
  File "/home/web/my_env/lib/python3.5/site-packages/elasticsearch/client/__init__.py", line 636, in search
    doc_type, '_search'), params=params, body=body)
  File "/home/web/my_env/lib/python3.5/site-packages/elasticsearch/transport.py", line 314, in perform_request
    status, headers, data = connection.perform_request(method, url, params, body, headers=headers, ignore=ignore, timeout=timeout)
  File "/home/web/my_env/lib/python3.5/site-packages/elasticsearch/connection/http_urllib3.py", line 161, in perform_request
    self._raise_error(response.status, raw_data)
  File "/home/web/my_env/lib/python3.5/site-packages/elasticsearch/connection/base.py", line 125, in _raise_error
    raise HTTP_EXCEPTIONS.get(status_code, TransportError)(status_code, error_message, additional_info)
elasticsearch.exceptions.NotFoundError: TransportError(404, 'index_not_found_exception', 'no such index')
2018-03-27 11:45:54,968 mongo_db.py[line:295] ERROR 错误的日期格式:
NoneType
2018-03-27 11:46:06,303 security_module.py[line:1288] ERROR elasticsearch Error:
Traceback (most recent call last):
  File "/home/web/my_env/projects/sq_platform/api/user/security_module.py", line 1280, in query_report2
    res = es.search(index=prefix, doc_type="daily_report", body=filter_dict)
  File "/home/web/my_env/lib/python3.5/site-packages/elasticsearch/client/utils.py", line 76, in _wrapped
    return func(*args, params=params, **kwargs)
  File "/home/web/my_env/lib/python3.5/site-packages/elasticsearch/client/__init__.py", line 636, in search
    doc_type, '_search'), params=params, body=body)
  File "/home/web/my_env/lib/python3.5/site-packages/elasticsearch/transport.py", line 314, in perform_request
    status, headers, data = connection.perform_request(method, url, params, body, headers=headers, ignore=ignore, timeout=timeout)
  File "/home/web/my_env/lib/python3.5/site-packages/elasticsearch/connection/http_urllib3.py", line 161, in perform_request
    self._raise_error(response.status, raw_data)
  File "/home/web/my_env/lib/python3.5/site-packages/elasticsearch/connection/base.py", line 125, in _raise_error
    raise HTTP_EXCEPTIONS.get(status_code, TransportError)(status_code, error_message, additional_info)
elasticsearch.exceptions.NotFoundError: TransportError(404, 'index_not_found_exception', 'no such index')
2018-03-27 11:46:07,166 user_view.py[line:313] ERROR Error! 
Traceback (most recent call last):
  File "/home/web/my_env/projects/sq_platform/api/user/user_view.py", line 235, in update_image
    file = upload_files[key]
  File "/home/web/my_env/lib/python3.5/site-packages/werkzeug/datastructures.py", line 428, in __getitem__
    raise exceptions.BadRequestKeyError(key)
werkzeug.exceptions.HTTPException.wrap.<locals>.newcls: 400 Bad Request: The browser (or proxy) sent a request that this server could not understand.
2018-03-27 11:53:20,039 mongo_db.py[line:295] ERROR 错误的日期格式:
NoneType
2018-03-27 11:57:22,451 security_module.py[line:1288] ERROR elasticsearch Error:
Traceback (most recent call last):
  File "/home/web/my_env/projects/sq_platform/api/user/security_module.py", line 1280, in query_report2
    res = es.search(index=prefix, doc_type="daily_report", body=filter_dict)
  File "/home/web/my_env/lib/python3.5/site-packages/elasticsearch/client/utils.py", line 76, in _wrapped
    return func(*args, params=params, **kwargs)
  File "/home/web/my_env/lib/python3.5/site-packages/elasticsearch/client/__init__.py", line 636, in search
    doc_type, '_search'), params=params, body=body)
  File "/home/web/my_env/lib/python3.5/site-packages/elasticsearch/transport.py", line 314, in perform_request
    status, headers, data = connection.perform_request(method, url, params, body, headers=headers, ignore=ignore, timeout=timeout)
  File "/home/web/my_env/lib/python3.5/site-packages/elasticsearch/connection/http_urllib3.py", line 161, in perform_request
    self._raise_error(response.status, raw_data)
  File "/home/web/my_env/lib/python3.5/site-packages/elasticsearch/connection/base.py", line 125, in _raise_error
    raise HTTP_EXCEPTIONS.get(status_code, TransportError)(status_code, error_message, additional_info)
elasticsearch.exceptions.NotFoundError: TransportError(404, 'index_not_found_exception', 'no such index')
