2018-03-18 15:11:13,558 mongo_db.py[line:913] ERROR mongo_db.save func Error,原因:not master
Traceback (most recent call last):
  File "/home/web/my_env/projects/sq_platform/mongo_db.py", line 904, in save
    save_id = ses.save(save_dict)
  File "/home/web/my_env/lib/python3.5/site-packages/pymongo/collection.py", line 2481, in save
    collation=collation)
  File "/home/web/my_env/lib/python3.5/site-packages/pymongo/collection.py", line 767, in _update
    _check_write_command_response([(0, result)])
  File "/home/web/my_env/lib/python3.5/site-packages/pymongo/helpers.py", line 315, in _check_write_command_response
    raise WriteError(error.get("errmsg"), error.get("code"), error)
pymongo.errors.WriteError: not master
2018-03-18 15:11:13,572 mongo_db.py[line:913] ERROR mongo_db.save func Error,原因:not master
Traceback (most recent call last):
  File "/home/web/my_env/projects/sq_platform/mongo_db.py", line 904, in save
    save_id = ses.save(save_dict)
  File "/home/web/my_env/lib/python3.5/site-packages/pymongo/collection.py", line 2481, in save
    collation=collation)
  File "/home/web/my_env/lib/python3.5/site-packages/pymongo/collection.py", line 767, in _update
    _check_write_command_response([(0, result)])
  File "/home/web/my_env/lib/python3.5/site-packages/pymongo/helpers.py", line 315, in _check_write_command_response
    raise WriteError(error.get("errmsg"), error.get("code"), error)
pymongo.errors.WriteError: not master
2018-03-18 15:22:24,954 mongo_db.py[line:913] ERROR mongo_db.save func Error,原因:not master
Traceback (most recent call last):
  File "/home/web/my_env/projects/sq_platform/mongo_db.py", line 904, in save
    save_id = ses.save(save_dict)
  File "/home/web/my_env/lib/python3.5/site-packages/pymongo/collection.py", line 2481, in save
    collation=collation)
  File "/home/web/my_env/lib/python3.5/site-packages/pymongo/collection.py", line 767, in _update
    _check_write_command_response([(0, result)])
  File "/home/web/my_env/lib/python3.5/site-packages/pymongo/helpers.py", line 315, in _check_write_command_response
    raise WriteError(error.get("errmsg"), error.get("code"), error)
pymongo.errors.WriteError: not master
2018-03-18 15:22:24,969 mongo_db.py[line:913] ERROR mongo_db.save func Error,原因:not master
Traceback (most recent call last):
  File "/home/web/my_env/projects/sq_platform/mongo_db.py", line 904, in save
    save_id = ses.save(save_dict)
  File "/home/web/my_env/lib/python3.5/site-packages/pymongo/collection.py", line 2481, in save
    collation=collation)
  File "/home/web/my_env/lib/python3.5/site-packages/pymongo/collection.py", line 767, in _update
    _check_write_command_response([(0, result)])
  File "/home/web/my_env/lib/python3.5/site-packages/pymongo/helpers.py", line 315, in _check_write_command_response
    raise WriteError(error.get("errmsg"), error.get("code"), error)
pymongo.errors.WriteError: not master
2018-03-18 18:55:32,264 mongo_db.py[line:913] ERROR mongo_db.save func Error,原因:not master
Traceback (most recent call last):
  File "/home/web/my_env/projects/sq_platform/mongo_db.py", line 904, in save
    save_id = ses.save(save_dict)
  File "/home/web/my_env/lib/python3.5/site-packages/pymongo/collection.py", line 2481, in save
    collation=collation)
  File "/home/web/my_env/lib/python3.5/site-packages/pymongo/collection.py", line 767, in _update
    _check_write_command_response([(0, result)])
  File "/home/web/my_env/lib/python3.5/site-packages/pymongo/helpers.py", line 315, in _check_write_command_response
    raise WriteError(error.get("errmsg"), error.get("code"), error)
pymongo.errors.WriteError: not master
2018-03-18 18:55:32,270 mongo_db.py[line:913] ERROR mongo_db.save func Error,原因:not master
Traceback (most recent call last):
  File "/home/web/my_env/projects/sq_platform/mongo_db.py", line 904, in save
    save_id = ses.save(save_dict)
  File "/home/web/my_env/lib/python3.5/site-packages/pymongo/collection.py", line 2481, in save
    collation=collation)
  File "/home/web/my_env/lib/python3.5/site-packages/pymongo/collection.py", line 767, in _update
    _check_write_command_response([(0, result)])
  File "/home/web/my_env/lib/python3.5/site-packages/pymongo/helpers.py", line 315, in _check_write_command_response
    raise WriteError(error.get("errmsg"), error.get("code"), error)
pymongo.errors.WriteError: not master
2018-03-19 08:43:38,255 mongo_db.py[line:913] ERROR mongo_db.save func Error,原因:not master
Traceback (most recent call last):
  File "/home/web/my_env/projects/sq_platform/mongo_db.py", line 904, in save
    save_id = ses.save(save_dict)
  File "/home/web/my_env/lib/python3.5/site-packages/pymongo/collection.py", line 2481, in save
    collation=collation)
  File "/home/web/my_env/lib/python3.5/site-packages/pymongo/collection.py", line 767, in _update
    _check_write_command_response([(0, result)])
  File "/home/web/my_env/lib/python3.5/site-packages/pymongo/helpers.py", line 315, in _check_write_command_response
    raise WriteError(error.get("errmsg"), error.get("code"), error)
pymongo.errors.WriteError: not master
2018-03-19 08:43:38,261 mongo_db.py[line:913] ERROR mongo_db.save func Error,原因:not master
Traceback (most recent call last):
  File "/home/web/my_env/projects/sq_platform/mongo_db.py", line 904, in save
    save_id = ses.save(save_dict)
  File "/home/web/my_env/lib/python3.5/site-packages/pymongo/collection.py", line 2481, in save
    collation=collation)
  File "/home/web/my_env/lib/python3.5/site-packages/pymongo/collection.py", line 767, in _update
    _check_write_command_response([(0, result)])
  File "/home/web/my_env/lib/python3.5/site-packages/pymongo/helpers.py", line 315, in _check_write_command_response
    raise WriteError(error.get("errmsg"), error.get("code"), error)
pymongo.errors.WriteError: not master
2018-03-19 08:44:58,245 mongo_db.py[line:913] ERROR mongo_db.save func Error,原因:not master
Traceback (most recent call last):
  File "/home/web/my_env/projects/sq_platform/mongo_db.py", line 904, in save
    save_id = ses.save(save_dict)
  File "/home/web/my_env/lib/python3.5/site-packages/pymongo/collection.py", line 2481, in save
    collation=collation)
  File "/home/web/my_env/lib/python3.5/site-packages/pymongo/collection.py", line 767, in _update
    _check_write_command_response([(0, result)])
  File "/home/web/my_env/lib/python3.5/site-packages/pymongo/helpers.py", line 315, in _check_write_command_response
    raise WriteError(error.get("errmsg"), error.get("code"), error)
pymongo.errors.WriteError: not master
2018-03-19 08:44:58,251 mongo_db.py[line:913] ERROR mongo_db.save func Error,原因:not master
Traceback (most recent call last):
  File "/home/web/my_env/projects/sq_platform/mongo_db.py", line 904, in save
    save_id = ses.save(save_dict)
  File "/home/web/my_env/lib/python3.5/site-packages/pymongo/collection.py", line 2481, in save
    collation=collation)
  File "/home/web/my_env/lib/python3.5/site-packages/pymongo/collection.py", line 767, in _update
    _check_write_command_response([(0, result)])
  File "/home/web/my_env/lib/python3.5/site-packages/pymongo/helpers.py", line 315, in _check_write_command_response
    raise WriteError(error.get("errmsg"), error.get("code"), error)
pymongo.errors.WriteError: not master
2018-03-19 08:45:08,290 mongo_db.py[line:913] ERROR mongo_db.save func Error,原因:not master
Traceback (most recent call last):
  File "/home/web/my_env/projects/sq_platform/mongo_db.py", line 904, in save
    save_id = ses.save(save_dict)
  File "/home/web/my_env/lib/python3.5/site-packages/pymongo/collection.py", line 2481, in save
    collation=collation)
  File "/home/web/my_env/lib/python3.5/site-packages/pymongo/collection.py", line 767, in _update
    _check_write_command_response([(0, result)])
  File "/home/web/my_env/lib/python3.5/site-packages/pymongo/helpers.py", line 315, in _check_write_command_response
    raise WriteError(error.get("errmsg"), error.get("code"), error)
pymongo.errors.WriteError: not master
2018-03-19 08:45:08,296 mongo_db.py[line:913] ERROR mongo_db.save func Error,原因:not master
Traceback (most recent call last):
  File "/home/web/my_env/projects/sq_platform/mongo_db.py", line 904, in save
    save_id = ses.save(save_dict)
  File "/home/web/my_env/lib/python3.5/site-packages/pymongo/collection.py", line 2481, in save
    collation=collation)
  File "/home/web/my_env/lib/python3.5/site-packages/pymongo/collection.py", line 767, in _update
    _check_write_command_response([(0, result)])
  File "/home/web/my_env/lib/python3.5/site-packages/pymongo/helpers.py", line 315, in _check_write_command_response
    raise WriteError(error.get("errmsg"), error.get("code"), error)
pymongo.errors.WriteError: not master
2018-03-19 09:40:44,148 mongo_db.py[line:913] ERROR mongo_db.save func Error,原因:not master
Traceback (most recent call last):
  File "/home/web/my_env/projects/sq_platform/mongo_db.py", line 904, in save
    save_id = ses.save(save_dict)
  File "/home/web/my_env/lib/python3.5/site-packages/pymongo/collection.py", line 2481, in save
    collation=collation)
  File "/home/web/my_env/lib/python3.5/site-packages/pymongo/collection.py", line 767, in _update
    _check_write_command_response([(0, result)])
  File "/home/web/my_env/lib/python3.5/site-packages/pymongo/helpers.py", line 315, in _check_write_command_response
    raise WriteError(error.get("errmsg"), error.get("code"), error)
pymongo.errors.WriteError: not master
2018-03-19 09:40:44,161 mongo_db.py[line:913] ERROR mongo_db.save func Error,原因:not master
Traceback (most recent call last):
  File "/home/web/my_env/projects/sq_platform/mongo_db.py", line 904, in save
    save_id = ses.save(save_dict)
  File "/home/web/my_env/lib/python3.5/site-packages/pymongo/collection.py", line 2481, in save
    collation=collation)
  File "/home/web/my_env/lib/python3.5/site-packages/pymongo/collection.py", line 767, in _update
    _check_write_command_response([(0, result)])
  File "/home/web/my_env/lib/python3.5/site-packages/pymongo/helpers.py", line 315, in _check_write_command_response
    raise WriteError(error.get("errmsg"), error.get("code"), error)
pymongo.errors.WriteError: not master
2018-03-19 10:47:19,145 mongo_db.py[line:913] ERROR mongo_db.save func Error,原因:not master
Traceback (most recent call last):
  File "/home/web/my_env/projects/sq_platform/mongo_db.py", line 904, in save
    save_id = ses.save(save_dict)
  File "/home/web/my_env/lib/python3.5/site-packages/pymongo/collection.py", line 2481, in save
    collation=collation)
  File "/home/web/my_env/lib/python3.5/site-packages/pymongo/collection.py", line 767, in _update
    _check_write_command_response([(0, result)])
  File "/home/web/my_env/lib/python3.5/site-packages/pymongo/helpers.py", line 315, in _check_write_command_response
    raise WriteError(error.get("errmsg"), error.get("code"), error)
pymongo.errors.WriteError: not master
2018-03-19 10:47:19,151 mongo_db.py[line:913] ERROR mongo_db.save func Error,原因:not master
Traceback (most recent call last):
  File "/home/web/my_env/projects/sq_platform/mongo_db.py", line 904, in save
    save_id = ses.save(save_dict)
  File "/home/web/my_env/lib/python3.5/site-packages/pymongo/collection.py", line 2481, in save
    collation=collation)
  File "/home/web/my_env/lib/python3.5/site-packages/pymongo/collection.py", line 767, in _update
    _check_write_command_response([(0, result)])
  File "/home/web/my_env/lib/python3.5/site-packages/pymongo/helpers.py", line 315, in _check_write_command_response
    raise WriteError(error.get("errmsg"), error.get("code"), error)
pymongo.errors.WriteError: not master
2018-03-19 11:15:25,144 mongo_db.py[line:913] ERROR mongo_db.save func Error,原因:not master
Traceback (most recent call last):
  File "/home/web/my_env/projects/sq_platform/mongo_db.py", line 904, in save
    save_id = ses.save(save_dict)
  File "/home/web/my_env/lib/python3.5/site-packages/pymongo/collection.py", line 2481, in save
    collation=collation)
  File "/home/web/my_env/lib/python3.5/site-packages/pymongo/collection.py", line 767, in _update
    _check_write_command_response([(0, result)])
  File "/home/web/my_env/lib/python3.5/site-packages/pymongo/helpers.py", line 315, in _check_write_command_response
    raise WriteError(error.get("errmsg"), error.get("code"), error)
pymongo.errors.WriteError: not master
2018-03-19 11:15:25,150 mongo_db.py[line:913] ERROR mongo_db.save func Error,原因:not master
Traceback (most recent call last):
  File "/home/web/my_env/projects/sq_platform/mongo_db.py", line 904, in save
    save_id = ses.save(save_dict)
  File "/home/web/my_env/lib/python3.5/site-packages/pymongo/collection.py", line 2481, in save
    collation=collation)
  File "/home/web/my_env/lib/python3.5/site-packages/pymongo/collection.py", line 767, in _update
    _check_write_command_response([(0, result)])
  File "/home/web/my_env/lib/python3.5/site-packages/pymongo/helpers.py", line 315, in _check_write_command_response
    raise WriteError(error.get("errmsg"), error.get("code"), error)
pymongo.errors.WriteError: not master
2018-03-19 11:45:07,192 mongo_db.py[line:913] ERROR mongo_db.save func Error,原因:could not find host matching read preference { mode: "primary", tags: [ {} ] } for set shard1
Traceback (most recent call last):
  File "/home/web/my_env/projects/sq_platform/mongo_db.py", line 904, in save
    save_id = ses.save(save_dict)
  File "/home/web/my_env/lib/python3.5/site-packages/pymongo/collection.py", line 2481, in save
    collation=collation)
  File "/home/web/my_env/lib/python3.5/site-packages/pymongo/collection.py", line 767, in _update
    _check_write_command_response([(0, result)])
  File "/home/web/my_env/lib/python3.5/site-packages/pymongo/helpers.py", line 315, in _check_write_command_response
    raise WriteError(error.get("errmsg"), error.get("code"), error)
pymongo.errors.WriteError: could not find host matching read preference { mode: "primary", tags: [ {} ] } for set shard1
2018-03-19 11:45:07,210 mongo_db.py[line:913] ERROR mongo_db.save func Error,原因:could not find host matching read preference { mode: "primary", tags: [ {} ] } for set shard1
Traceback (most recent call last):
  File "/home/web/my_env/projects/sq_platform/mongo_db.py", line 904, in save
    save_id = ses.save(save_dict)
  File "/home/web/my_env/lib/python3.5/site-packages/pymongo/collection.py", line 2481, in save
    collation=collation)
  File "/home/web/my_env/lib/python3.5/site-packages/pymongo/collection.py", line 767, in _update
    _check_write_command_response([(0, result)])
  File "/home/web/my_env/lib/python3.5/site-packages/pymongo/helpers.py", line 315, in _check_write_command_response
    raise WriteError(error.get("errmsg"), error.get("code"), error)
pymongo.errors.WriteError: could not find host matching read preference { mode: "primary", tags: [ {} ] } for set shard1
2018-03-19 11:45:12,150 mongo_db.py[line:913] ERROR mongo_db.save func Error,原因:could not find host matching read preference { mode: "primary", tags: [ {} ] } for set shard1
Traceback (most recent call last):
  File "/home/web/my_env/projects/sq_platform/mongo_db.py", line 904, in save
    save_id = ses.save(save_dict)
  File "/home/web/my_env/lib/python3.5/site-packages/pymongo/collection.py", line 2481, in save
    collation=collation)
  File "/home/web/my_env/lib/python3.5/site-packages/pymongo/collection.py", line 767, in _update
    _check_write_command_response([(0, result)])
  File "/home/web/my_env/lib/python3.5/site-packages/pymongo/helpers.py", line 315, in _check_write_command_response
    raise WriteError(error.get("errmsg"), error.get("code"), error)
pymongo.errors.WriteError: could not find host matching read preference { mode: "primary", tags: [ {} ] } for set shard1
2018-03-19 11:45:12,167 mongo_db.py[line:913] ERROR mongo_db.save func Error,原因:could not find host matching read preference { mode: "primary", tags: [ {} ] } for set shard1
Traceback (most recent call last):
  File "/home/web/my_env/projects/sq_platform/mongo_db.py", line 904, in save
    save_id = ses.save(save_dict)
  File "/home/web/my_env/lib/python3.5/site-packages/pymongo/collection.py", line 2481, in save
    collation=collation)
  File "/home/web/my_env/lib/python3.5/site-packages/pymongo/collection.py", line 767, in _update
    _check_write_command_response([(0, result)])
  File "/home/web/my_env/lib/python3.5/site-packages/pymongo/helpers.py", line 315, in _check_write_command_response
    raise WriteError(error.get("errmsg"), error.get("code"), error)
pymongo.errors.WriteError: could not find host matching read preference { mode: "primary", tags: [ {} ] } for set shard1
2018-03-19 11:45:27,235 mongo_db.py[line:913] ERROR mongo_db.save func Error,原因:not master
Traceback (most recent call last):
  File "/home/web/my_env/projects/sq_platform/mongo_db.py", line 904, in save
    save_id = ses.save(save_dict)
  File "/home/web/my_env/lib/python3.5/site-packages/pymongo/collection.py", line 2481, in save
    collation=collation)
  File "/home/web/my_env/lib/python3.5/site-packages/pymongo/collection.py", line 767, in _update
    _check_write_command_response([(0, result)])
  File "/home/web/my_env/lib/python3.5/site-packages/pymongo/helpers.py", line 315, in _check_write_command_response
    raise WriteError(error.get("errmsg"), error.get("code"), error)
pymongo.errors.WriteError: not master
2018-03-19 11:45:27,252 mongo_db.py[line:913] ERROR mongo_db.save func Error,原因:not master
Traceback (most recent call last):
  File "/home/web/my_env/projects/sq_platform/mongo_db.py", line 904, in save
    save_id = ses.save(save_dict)
  File "/home/web/my_env/lib/python3.5/site-packages/pymongo/collection.py", line 2481, in save
    collation=collation)
  File "/home/web/my_env/lib/python3.5/site-packages/pymongo/collection.py", line 767, in _update
    _check_write_command_response([(0, result)])
  File "/home/web/my_env/lib/python3.5/site-packages/pymongo/helpers.py", line 315, in _check_write_command_response
    raise WriteError(error.get("errmsg"), error.get("code"), error)
pymongo.errors.WriteError: not master
2018-03-19 11:45:32,172 mongo_db.py[line:913] ERROR mongo_db.save func Error,原因:not master
Traceback (most recent call last):
  File "/home/web/my_env/projects/sq_platform/mongo_db.py", line 904, in save
    save_id = ses.save(save_dict)
  File "/home/web/my_env/lib/python3.5/site-packages/pymongo/collection.py", line 2481, in save
    collation=collation)
  File "/home/web/my_env/lib/python3.5/site-packages/pymongo/collection.py", line 767, in _update
    _check_write_command_response([(0, result)])
  File "/home/web/my_env/lib/python3.5/site-packages/pymongo/helpers.py", line 315, in _check_write_command_response
    raise WriteError(error.get("errmsg"), error.get("code"), error)
pymongo.errors.WriteError: not master
2018-03-19 11:45:32,187 mongo_db.py[line:913] ERROR mongo_db.save func Error,原因:not master
Traceback (most recent call last):
  File "/home/web/my_env/projects/sq_platform/mongo_db.py", line 904, in save
    save_id = ses.save(save_dict)
  File "/home/web/my_env/lib/python3.5/site-packages/pymongo/collection.py", line 2481, in save
    collation=collation)
  File "/home/web/my_env/lib/python3.5/site-packages/pymongo/collection.py", line 767, in _update
    _check_write_command_response([(0, result)])
  File "/home/web/my_env/lib/python3.5/site-packages/pymongo/helpers.py", line 315, in _check_write_command_response
    raise WriteError(error.get("errmsg"), error.get("code"), error)
pymongo.errors.WriteError: not master
2018-03-19 11:45:37,155 mongo_db.py[line:913] ERROR mongo_db.save func Error,原因:not master
Traceback (most recent call last):
  File "/home/web/my_env/projects/sq_platform/mongo_db.py", line 904, in save
    save_id = ses.save(save_dict)
  File "/home/web/my_env/lib/python3.5/site-packages/pymongo/collection.py", line 2481, in save
    collation=collation)
  File "/home/web/my_env/lib/python3.5/site-packages/pymongo/collection.py", line 767, in _update
    _check_write_command_response([(0, result)])
  File "/home/web/my_env/lib/python3.5/site-packages/pymongo/helpers.py", line 315, in _check_write_command_response
    raise WriteError(error.get("errmsg"), error.get("code"), error)
pymongo.errors.WriteError: not master
2018-03-19 11:45:37,171 mongo_db.py[line:913] ERROR mongo_db.save func Error,原因:not master
Traceback (most recent call last):
  File "/home/web/my_env/projects/sq_platform/mongo_db.py", line 904, in save
    save_id = ses.save(save_dict)
  File "/home/web/my_env/lib/python3.5/site-packages/pymongo/collection.py", line 2481, in save
    collation=collation)
  File "/home/web/my_env/lib/python3.5/site-packages/pymongo/collection.py", line 767, in _update
    _check_write_command_response([(0, result)])
  File "/home/web/my_env/lib/python3.5/site-packages/pymongo/helpers.py", line 315, in _check_write_command_response
    raise WriteError(error.get("errmsg"), error.get("code"), error)
pymongo.errors.WriteError: not master
2018-03-19 11:45:42,155 mongo_db.py[line:913] ERROR mongo_db.save func Error,原因:not master
Traceback (most recent call last):
  File "/home/web/my_env/projects/sq_platform/mongo_db.py", line 904, in save
    save_id = ses.save(save_dict)
  File "/home/web/my_env/lib/python3.5/site-packages/pymongo/collection.py", line 2481, in save
    collation=collation)
  File "/home/web/my_env/lib/python3.5/site-packages/pymongo/collection.py", line 767, in _update
    _check_write_command_response([(0, result)])
  File "/home/web/my_env/lib/python3.5/site-packages/pymongo/helpers.py", line 315, in _check_write_command_response
    raise WriteError(error.get("errmsg"), error.get("code"), error)
pymongo.errors.WriteError: not master
2018-03-19 11:45:42,171 mongo_db.py[line:913] ERROR mongo_db.save func Error,原因:not master
Traceback (most recent call last):
  File "/home/web/my_env/projects/sq_platform/mongo_db.py", line 904, in save
    save_id = ses.save(save_dict)
  File "/home/web/my_env/lib/python3.5/site-packages/pymongo/collection.py", line 2481, in save
    collation=collation)
  File "/home/web/my_env/lib/python3.5/site-packages/pymongo/collection.py", line 767, in _update
    _check_write_command_response([(0, result)])
  File "/home/web/my_env/lib/python3.5/site-packages/pymongo/helpers.py", line 315, in _check_write_command_response
    raise WriteError(error.get("errmsg"), error.get("code"), error)
pymongo.errors.WriteError: not master
2018-03-19 11:45:47,198 mongo_db.py[line:913] ERROR mongo_db.save func Error,原因:not master
Traceback (most recent call last):
  File "/home/web/my_env/projects/sq_platform/mongo_db.py", line 904, in save
    save_id = ses.save(save_dict)
  File "/home/web/my_env/lib/python3.5/site-packages/pymongo/collection.py", line 2481, in save
    collation=collation)
  File "/home/web/my_env/lib/python3.5/site-packages/pymongo/collection.py", line 767, in _update
    _check_write_command_response([(0, result)])
  File "/home/web/my_env/lib/python3.5/site-packages/pymongo/helpers.py", line 315, in _check_write_command_response
    raise WriteError(error.get("errmsg"), error.get("code"), error)
pymongo.errors.WriteError: not master
2018-03-19 11:45:47,215 mongo_db.py[line:913] ERROR mongo_db.save func Error,原因:not master
Traceback (most recent call last):
  File "/home/web/my_env/projects/sq_platform/mongo_db.py", line 904, in save
    save_id = ses.save(save_dict)
  File "/home/web/my_env/lib/python3.5/site-packages/pymongo/collection.py", line 2481, in save
    collation=collation)
  File "/home/web/my_env/lib/python3.5/site-packages/pymongo/collection.py", line 767, in _update
    _check_write_command_response([(0, result)])
  File "/home/web/my_env/lib/python3.5/site-packages/pymongo/helpers.py", line 315, in _check_write_command_response
    raise WriteError(error.get("errmsg"), error.get("code"), error)
pymongo.errors.WriteError: not master
2018-03-19 11:45:52,170 mongo_db.py[line:913] ERROR mongo_db.save func Error,原因:not master
Traceback (most recent call last):
  File "/home/web/my_env/projects/sq_platform/mongo_db.py", line 904, in save
    save_id = ses.save(save_dict)
  File "/home/web/my_env/lib/python3.5/site-packages/pymongo/collection.py", line 2481, in save
    collation=collation)
  File "/home/web/my_env/lib/python3.5/site-packages/pymongo/collection.py", line 767, in _update
    _check_write_command_response([(0, result)])
  File "/home/web/my_env/lib/python3.5/site-packages/pymongo/helpers.py", line 315, in _check_write_command_response
    raise WriteError(error.get("errmsg"), error.get("code"), error)
pymongo.errors.WriteError: not master
2018-03-19 11:45:52,186 mongo_db.py[line:913] ERROR mongo_db.save func Error,原因:not master
Traceback (most recent call last):
  File "/home/web/my_env/projects/sq_platform/mongo_db.py", line 904, in save
    save_id = ses.save(save_dict)
  File "/home/web/my_env/lib/python3.5/site-packages/pymongo/collection.py", line 2481, in save
    collation=collation)
  File "/home/web/my_env/lib/python3.5/site-packages/pymongo/collection.py", line 767, in _update
    _check_write_command_response([(0, result)])
  File "/home/web/my_env/lib/python3.5/site-packages/pymongo/helpers.py", line 315, in _check_write_command_response
    raise WriteError(error.get("errmsg"), error.get("code"), error)
pymongo.errors.WriteError: not master
2018-03-19 11:45:57,155 mongo_db.py[line:913] ERROR mongo_db.save func Error,原因:not master
Traceback (most recent call last):
  File "/home/web/my_env/projects/sq_platform/mongo_db.py", line 904, in save
    save_id = ses.save(save_dict)
  File "/home/web/my_env/lib/python3.5/site-packages/pymongo/collection.py", line 2481, in save
    collation=collation)
  File "/home/web/my_env/lib/python3.5/site-packages/pymongo/collection.py", line 767, in _update
    _check_write_command_response([(0, result)])
  File "/home/web/my_env/lib/python3.5/site-packages/pymongo/helpers.py", line 315, in _check_write_command_response
    raise WriteError(error.get("errmsg"), error.get("code"), error)
pymongo.errors.WriteError: not master
2018-03-19 11:45:57,171 mongo_db.py[line:913] ERROR mongo_db.save func Error,原因:not master
Traceback (most recent call last):
  File "/home/web/my_env/projects/sq_platform/mongo_db.py", line 904, in save
    save_id = ses.save(save_dict)
  File "/home/web/my_env/lib/python3.5/site-packages/pymongo/collection.py", line 2481, in save
    collation=collation)
  File "/home/web/my_env/lib/python3.5/site-packages/pymongo/collection.py", line 767, in _update
    _check_write_command_response([(0, result)])
  File "/home/web/my_env/lib/python3.5/site-packages/pymongo/helpers.py", line 315, in _check_write_command_response
    raise WriteError(error.get("errmsg"), error.get("code"), error)
pymongo.errors.WriteError: not master
2018-03-19 11:46:02,338 mongo_db.py[line:913] ERROR mongo_db.save func Error,原因:not master
Traceback (most recent call last):
  File "/home/web/my_env/projects/sq_platform/mongo_db.py", line 904, in save
    save_id = ses.save(save_dict)
  File "/home/web/my_env/lib/python3.5/site-packages/pymongo/collection.py", line 2481, in save
    collation=collation)
  File "/home/web/my_env/lib/python3.5/site-packages/pymongo/collection.py", line 767, in _update
    _check_write_command_response([(0, result)])
  File "/home/web/my_env/lib/python3.5/site-packages/pymongo/helpers.py", line 315, in _check_write_command_response
    raise WriteError(error.get("errmsg"), error.get("code"), error)
pymongo.errors.WriteError: not master
2018-03-19 11:46:02,354 mongo_db.py[line:913] ERROR mongo_db.save func Error,原因:not master
Traceback (most recent call last):
  File "/home/web/my_env/projects/sq_platform/mongo_db.py", line 904, in save
    save_id = ses.save(save_dict)
  File "/home/web/my_env/lib/python3.5/site-packages/pymongo/collection.py", line 2481, in save
    collation=collation)
  File "/home/web/my_env/lib/python3.5/site-packages/pymongo/collection.py", line 767, in _update
    _check_write_command_response([(0, result)])
  File "/home/web/my_env/lib/python3.5/site-packages/pymongo/helpers.py", line 315, in _check_write_command_response
    raise WriteError(error.get("errmsg"), error.get("code"), error)
pymongo.errors.WriteError: not master
2018-03-19 12:21:05,131 mongo_db.py[line:913] ERROR mongo_db.save func Error,原因:not master
Traceback (most recent call last):
  File "/home/web/my_env/projects/sq_platform/mongo_db.py", line 904, in save
    save_id = ses.save(save_dict)
  File "/home/web/my_env/lib/python3.5/site-packages/pymongo/collection.py", line 2481, in save
    collation=collation)
  File "/home/web/my_env/lib/python3.5/site-packages/pymongo/collection.py", line 767, in _update
    _check_write_command_response([(0, result)])
  File "/home/web/my_env/lib/python3.5/site-packages/pymongo/helpers.py", line 315, in _check_write_command_response
    raise WriteError(error.get("errmsg"), error.get("code"), error)
pymongo.errors.WriteError: not master
2018-03-19 12:21:05,139 mongo_db.py[line:913] ERROR mongo_db.save func Error,原因:not master
Traceback (most recent call last):
  File "/home/web/my_env/projects/sq_platform/mongo_db.py", line 904, in save
    save_id = ses.save(save_dict)
  File "/home/web/my_env/lib/python3.5/site-packages/pymongo/collection.py", line 2481, in save
    collation=collation)
  File "/home/web/my_env/lib/python3.5/site-packages/pymongo/collection.py", line 767, in _update
    _check_write_command_response([(0, result)])
  File "/home/web/my_env/lib/python3.5/site-packages/pymongo/helpers.py", line 315, in _check_write_command_response
    raise WriteError(error.get("errmsg"), error.get("code"), error)
pymongo.errors.WriteError: not master
2018-03-19 12:21:05,850 mongo_db.py[line:913] ERROR mongo_db.save func Error,原因:not master
Traceback (most recent call last):
  File "/home/web/my_env/projects/sq_platform/mongo_db.py", line 904, in save
    save_id = ses.save(save_dict)
  File "/home/web/my_env/lib/python3.5/site-packages/pymongo/collection.py", line 2481, in save
    collation=collation)
  File "/home/web/my_env/lib/python3.5/site-packages/pymongo/collection.py", line 767, in _update
    _check_write_command_response([(0, result)])
  File "/home/web/my_env/lib/python3.5/site-packages/pymongo/helpers.py", line 315, in _check_write_command_response
    raise WriteError(error.get("errmsg"), error.get("code"), error)
pymongo.errors.WriteError: not master
2018-03-19 12:21:05,856 mongo_db.py[line:913] ERROR mongo_db.save func Error,原因:not master
Traceback (most recent call last):
  File "/home/web/my_env/projects/sq_platform/mongo_db.py", line 904, in save
    save_id = ses.save(save_dict)
  File "/home/web/my_env/lib/python3.5/site-packages/pymongo/collection.py", line 2481, in save
    collation=collation)
  File "/home/web/my_env/lib/python3.5/site-packages/pymongo/collection.py", line 767, in _update
    _check_write_command_response([(0, result)])
  File "/home/web/my_env/lib/python3.5/site-packages/pymongo/helpers.py", line 315, in _check_write_command_response
    raise WriteError(error.get("errmsg"), error.get("code"), error)
pymongo.errors.WriteError: not master
2018-03-19 12:33:01,249 mongo_db.py[line:913] ERROR mongo_db.save func Error,原因:not master
Traceback (most recent call last):
  File "/home/web/my_env/projects/sq_platform/mongo_db.py", line 904, in save
    save_id = ses.save(save_dict)
  File "/home/web/my_env/lib/python3.5/site-packages/pymongo/collection.py", line 2481, in save
    collation=collation)
  File "/home/web/my_env/lib/python3.5/site-packages/pymongo/collection.py", line 767, in _update
    _check_write_command_response([(0, result)])
  File "/home/web/my_env/lib/python3.5/site-packages/pymongo/helpers.py", line 315, in _check_write_command_response
    raise WriteError(error.get("errmsg"), error.get("code"), error)
pymongo.errors.WriteError: not master
2018-03-19 12:33:01,255 mongo_db.py[line:913] ERROR mongo_db.save func Error,原因:not master
Traceback (most recent call last):
  File "/home/web/my_env/projects/sq_platform/mongo_db.py", line 904, in save
    save_id = ses.save(save_dict)
  File "/home/web/my_env/lib/python3.5/site-packages/pymongo/collection.py", line 2481, in save
    collation=collation)
  File "/home/web/my_env/lib/python3.5/site-packages/pymongo/collection.py", line 767, in _update
    _check_write_command_response([(0, result)])
  File "/home/web/my_env/lib/python3.5/site-packages/pymongo/helpers.py", line 315, in _check_write_command_response
    raise WriteError(error.get("errmsg"), error.get("code"), error)
pymongo.errors.WriteError: not master
2018-03-19 14:21:52,289 mongo_db.py[line:913] ERROR mongo_db.save func Error,原因:not master
Traceback (most recent call last):
  File "/home/web/my_env/projects/sq_platform/mongo_db.py", line 904, in save
    save_id = ses.save(save_dict)
  File "/home/web/my_env/lib/python3.5/site-packages/pymongo/collection.py", line 2481, in save
    collation=collation)
  File "/home/web/my_env/lib/python3.5/site-packages/pymongo/collection.py", line 767, in _update
    _check_write_command_response([(0, result)])
  File "/home/web/my_env/lib/python3.5/site-packages/pymongo/helpers.py", line 315, in _check_write_command_response
    raise WriteError(error.get("errmsg"), error.get("code"), error)
pymongo.errors.WriteError: not master
2018-03-19 14:21:52,295 mongo_db.py[line:913] ERROR mongo_db.save func Error,原因:not master
Traceback (most recent call last):
  File "/home/web/my_env/projects/sq_platform/mongo_db.py", line 904, in save
    save_id = ses.save(save_dict)
  File "/home/web/my_env/lib/python3.5/site-packages/pymongo/collection.py", line 2481, in save
    collation=collation)
  File "/home/web/my_env/lib/python3.5/site-packages/pymongo/collection.py", line 767, in _update
    _check_write_command_response([(0, result)])
  File "/home/web/my_env/lib/python3.5/site-packages/pymongo/helpers.py", line 315, in _check_write_command_response
    raise WriteError(error.get("errmsg"), error.get("code"), error)
pymongo.errors.WriteError: not master
2018-03-19 14:21:52,379 mongo_db.py[line:913] ERROR mongo_db.save func Error,原因:not master
Traceback (most recent call last):
  File "/home/web/my_env/projects/sq_platform/mongo_db.py", line 904, in save
    save_id = ses.save(save_dict)
  File "/home/web/my_env/lib/python3.5/site-packages/pymongo/collection.py", line 2481, in save
    collation=collation)
  File "/home/web/my_env/lib/python3.5/site-packages/pymongo/collection.py", line 767, in _update
    _check_write_command_response([(0, result)])
  File "/home/web/my_env/lib/python3.5/site-packages/pymongo/helpers.py", line 315, in _check_write_command_response
    raise WriteError(error.get("errmsg"), error.get("code"), error)
pymongo.errors.WriteError: not master
2018-03-19 14:21:52,385 mongo_db.py[line:913] ERROR mongo_db.save func Error,原因:not master
Traceback (most recent call last):
  File "/home/web/my_env/projects/sq_platform/mongo_db.py", line 904, in save
    save_id = ses.save(save_dict)
  File "/home/web/my_env/lib/python3.5/site-packages/pymongo/collection.py", line 2481, in save
    collation=collation)
  File "/home/web/my_env/lib/python3.5/site-packages/pymongo/collection.py", line 767, in _update
    _check_write_command_response([(0, result)])
  File "/home/web/my_env/lib/python3.5/site-packages/pymongo/helpers.py", line 315, in _check_write_command_response
    raise WriteError(error.get("errmsg"), error.get("code"), error)
pymongo.errors.WriteError: not master
2018-03-19 14:21:55,133 mongo_db.py[line:913] ERROR mongo_db.save func Error,原因:not master
Traceback (most recent call last):
  File "/home/web/my_env/projects/sq_platform/mongo_db.py", line 904, in save
    save_id = ses.save(save_dict)
  File "/home/web/my_env/lib/python3.5/site-packages/pymongo/collection.py", line 2481, in save
    collation=collation)
  File "/home/web/my_env/lib/python3.5/site-packages/pymongo/collection.py", line 767, in _update
    _check_write_command_response([(0, result)])
  File "/home/web/my_env/lib/python3.5/site-packages/pymongo/helpers.py", line 315, in _check_write_command_response
    raise WriteError(error.get("errmsg"), error.get("code"), error)
pymongo.errors.WriteError: not master
2018-03-19 14:21:55,139 mongo_db.py[line:913] ERROR mongo_db.save func Error,原因:not master
Traceback (most recent call last):
  File "/home/web/my_env/projects/sq_platform/mongo_db.py", line 904, in save
    save_id = ses.save(save_dict)
  File "/home/web/my_env/lib/python3.5/site-packages/pymongo/collection.py", line 2481, in save
    collation=collation)
  File "/home/web/my_env/lib/python3.5/site-packages/pymongo/collection.py", line 767, in _update
    _check_write_command_response([(0, result)])
  File "/home/web/my_env/lib/python3.5/site-packages/pymongo/helpers.py", line 315, in _check_write_command_response
    raise WriteError(error.get("errmsg"), error.get("code"), error)
pymongo.errors.WriteError: not master
2018-03-19 14:21:55,839 mongo_db.py[line:913] ERROR mongo_db.save func Error,原因:not master
Traceback (most recent call last):
  File "/home/web/my_env/projects/sq_platform/mongo_db.py", line 904, in save
    save_id = ses.save(save_dict)
  File "/home/web/my_env/lib/python3.5/site-packages/pymongo/collection.py", line 2481, in save
    collation=collation)
  File "/home/web/my_env/lib/python3.5/site-packages/pymongo/collection.py", line 767, in _update
    _check_write_command_response([(0, result)])
  File "/home/web/my_env/lib/python3.5/site-packages/pymongo/helpers.py", line 315, in _check_write_command_response
    raise WriteError(error.get("errmsg"), error.get("code"), error)
pymongo.errors.WriteError: not master
2018-03-19 14:21:55,845 mongo_db.py[line:913] ERROR mongo_db.save func Error,原因:not master
Traceback (most recent call last):
  File "/home/web/my_env/projects/sq_platform/mongo_db.py", line 904, in save
    save_id = ses.save(save_dict)
  File "/home/web/my_env/lib/python3.5/site-packages/pymongo/collection.py", line 2481, in save
    collation=collation)
  File "/home/web/my_env/lib/python3.5/site-packages/pymongo/collection.py", line 767, in _update
    _check_write_command_response([(0, result)])
  File "/home/web/my_env/lib/python3.5/site-packages/pymongo/helpers.py", line 315, in _check_write_command_response
    raise WriteError(error.get("errmsg"), error.get("code"), error)
pymongo.errors.WriteError: not master
2018-03-19 14:23:11,190 mongo_db.py[line:913] ERROR mongo_db.save func Error,原因:not master
Traceback (most recent call last):
  File "/home/web/my_env/projects/sq_platform/mongo_db.py", line 904, in save
    save_id = ses.save(save_dict)
  File "/home/web/my_env/lib/python3.5/site-packages/pymongo/collection.py", line 2481, in save
    collation=collation)
  File "/home/web/my_env/lib/python3.5/site-packages/pymongo/collection.py", line 767, in _update
    _check_write_command_response([(0, result)])
  File "/home/web/my_env/lib/python3.5/site-packages/pymongo/helpers.py", line 315, in _check_write_command_response
    raise WriteError(error.get("errmsg"), error.get("code"), error)
pymongo.errors.WriteError: not master
2018-03-19 14:23:11,200 mongo_db.py[line:913] ERROR mongo_db.save func Error,原因:not master
Traceback (most recent call last):
  File "/home/web/my_env/projects/sq_platform/mongo_db.py", line 904, in save
    save_id = ses.save(save_dict)
  File "/home/web/my_env/lib/python3.5/site-packages/pymongo/collection.py", line 2481, in save
    collation=collation)
  File "/home/web/my_env/lib/python3.5/site-packages/pymongo/collection.py", line 767, in _update
    _check_write_command_response([(0, result)])
  File "/home/web/my_env/lib/python3.5/site-packages/pymongo/helpers.py", line 315, in _check_write_command_response
    raise WriteError(error.get("errmsg"), error.get("code"), error)
pymongo.errors.WriteError: not master
2018-03-19 14:23:12,226 mongo_db.py[line:913] ERROR mongo_db.save func Error,原因:not master
Traceback (most recent call last):
  File "/home/web/my_env/projects/sq_platform/mongo_db.py", line 904, in save
    save_id = ses.save(save_dict)
  File "/home/web/my_env/lib/python3.5/site-packages/pymongo/collection.py", line 2481, in save
    collation=collation)
  File "/home/web/my_env/lib/python3.5/site-packages/pymongo/collection.py", line 767, in _update
    _check_write_command_response([(0, result)])
  File "/home/web/my_env/lib/python3.5/site-packages/pymongo/helpers.py", line 315, in _check_write_command_response
    raise WriteError(error.get("errmsg"), error.get("code"), error)
pymongo.errors.WriteError: not master
2018-03-19 14:23:12,234 mongo_db.py[line:913] ERROR mongo_db.save func Error,原因:not master
Traceback (most recent call last):
  File "/home/web/my_env/projects/sq_platform/mongo_db.py", line 904, in save
    save_id = ses.save(save_dict)
  File "/home/web/my_env/lib/python3.5/site-packages/pymongo/collection.py", line 2481, in save
    collation=collation)
  File "/home/web/my_env/lib/python3.5/site-packages/pymongo/collection.py", line 767, in _update
    _check_write_command_response([(0, result)])
  File "/home/web/my_env/lib/python3.5/site-packages/pymongo/helpers.py", line 315, in _check_write_command_response
    raise WriteError(error.get("errmsg"), error.get("code"), error)
pymongo.errors.WriteError: not master
2018-03-19 14:23:16,159 mongo_db.py[line:913] ERROR mongo_db.save func Error,原因:not master
Traceback (most recent call last):
  File "/home/web/my_env/projects/sq_platform/mongo_db.py", line 904, in save
    save_id = ses.save(save_dict)
  File "/home/web/my_env/lib/python3.5/site-packages/pymongo/collection.py", line 2481, in save
    collation=collation)
  File "/home/web/my_env/lib/python3.5/site-packages/pymongo/collection.py", line 767, in _update
    _check_write_command_response([(0, result)])
  File "/home/web/my_env/lib/python3.5/site-packages/pymongo/helpers.py", line 315, in _check_write_command_response
    raise WriteError(error.get("errmsg"), error.get("code"), error)
pymongo.errors.WriteError: not master
2018-03-19 14:23:16,169 mongo_db.py[line:913] ERROR mongo_db.save func Error,原因:not master
Traceback (most recent call last):
  File "/home/web/my_env/projects/sq_platform/mongo_db.py", line 904, in save
    save_id = ses.save(save_dict)
  File "/home/web/my_env/lib/python3.5/site-packages/pymongo/collection.py", line 2481, in save
    collation=collation)
  File "/home/web/my_env/lib/python3.5/site-packages/pymongo/collection.py", line 767, in _update
    _check_write_command_response([(0, result)])
  File "/home/web/my_env/lib/python3.5/site-packages/pymongo/helpers.py", line 315, in _check_write_command_response
    raise WriteError(error.get("errmsg"), error.get("code"), error)
pymongo.errors.WriteError: not master
2018-03-19 14:23:21,154 mongo_db.py[line:913] ERROR mongo_db.save func Error,原因:not master
Traceback (most recent call last):
  File "/home/web/my_env/projects/sq_platform/mongo_db.py", line 904, in save
    save_id = ses.save(save_dict)
  File "/home/web/my_env/lib/python3.5/site-packages/pymongo/collection.py", line 2481, in save
    collation=collation)
  File "/home/web/my_env/lib/python3.5/site-packages/pymongo/collection.py", line 767, in _update
    _check_write_command_response([(0, result)])
  File "/home/web/my_env/lib/python3.5/site-packages/pymongo/helpers.py", line 315, in _check_write_command_response
    raise WriteError(error.get("errmsg"), error.get("code"), error)
pymongo.errors.WriteError: not master
2018-03-19 14:23:21,160 mongo_db.py[line:913] ERROR mongo_db.save func Error,原因:not master
Traceback (most recent call last):
  File "/home/web/my_env/projects/sq_platform/mongo_db.py", line 904, in save
    save_id = ses.save(save_dict)
  File "/home/web/my_env/lib/python3.5/site-packages/pymongo/collection.py", line 2481, in save
    collation=collation)
  File "/home/web/my_env/lib/python3.5/site-packages/pymongo/collection.py", line 767, in _update
    _check_write_command_response([(0, result)])
  File "/home/web/my_env/lib/python3.5/site-packages/pymongo/helpers.py", line 315, in _check_write_command_response
    raise WriteError(error.get("errmsg"), error.get("code"), error)
pymongo.errors.WriteError: not master
2018-03-19 15:02:06,139 mongo_db.py[line:913] ERROR mongo_db.save func Error,原因:not master
Traceback (most recent call last):
  File "/home/web/my_env/projects/sq_platform/mongo_db.py", line 904, in save
    save_id = ses.save(save_dict)
  File "/home/web/my_env/lib/python3.5/site-packages/pymongo/collection.py", line 2481, in save
    collation=collation)
  File "/home/web/my_env/lib/python3.5/site-packages/pymongo/collection.py", line 767, in _update
    _check_write_command_response([(0, result)])
  File "/home/web/my_env/lib/python3.5/site-packages/pymongo/helpers.py", line 315, in _check_write_command_response
    raise WriteError(error.get("errmsg"), error.get("code"), error)
pymongo.errors.WriteError: not master
2018-03-19 15:02:06,145 mongo_db.py[line:913] ERROR mongo_db.save func Error,原因:not master
Traceback (most recent call last):
  File "/home/web/my_env/projects/sq_platform/mongo_db.py", line 904, in save
    save_id = ses.save(save_dict)
  File "/home/web/my_env/lib/python3.5/site-packages/pymongo/collection.py", line 2481, in save
    collation=collation)
  File "/home/web/my_env/lib/python3.5/site-packages/pymongo/collection.py", line 767, in _update
    _check_write_command_response([(0, result)])
  File "/home/web/my_env/lib/python3.5/site-packages/pymongo/helpers.py", line 315, in _check_write_command_response
    raise WriteError(error.get("errmsg"), error.get("code"), error)
pymongo.errors.WriteError: not master
2018-03-19 15:02:11,118 mongo_db.py[line:913] ERROR mongo_db.save func Error,原因:not master
Traceback (most recent call last):
  File "/home/web/my_env/projects/sq_platform/mongo_db.py", line 904, in save
    save_id = ses.save(save_dict)
  File "/home/web/my_env/lib/python3.5/site-packages/pymongo/collection.py", line 2481, in save
    collation=collation)
  File "/home/web/my_env/lib/python3.5/site-packages/pymongo/collection.py", line 767, in _update
    _check_write_command_response([(0, result)])
  File "/home/web/my_env/lib/python3.5/site-packages/pymongo/helpers.py", line 315, in _check_write_command_response
    raise WriteError(error.get("errmsg"), error.get("code"), error)
pymongo.errors.WriteError: not master
2018-03-19 15:02:11,123 mongo_db.py[line:913] ERROR mongo_db.save func Error,原因:not master
Traceback (most recent call last):
  File "/home/web/my_env/projects/sq_platform/mongo_db.py", line 904, in save
    save_id = ses.save(save_dict)
  File "/home/web/my_env/lib/python3.5/site-packages/pymongo/collection.py", line 2481, in save
    collation=collation)
  File "/home/web/my_env/lib/python3.5/site-packages/pymongo/collection.py", line 767, in _update
    _check_write_command_response([(0, result)])
  File "/home/web/my_env/lib/python3.5/site-packages/pymongo/helpers.py", line 315, in _check_write_command_response
    raise WriteError(error.get("errmsg"), error.get("code"), error)
pymongo.errors.WriteError: not master
2018-03-19 15:09:42,057 mongo_db.py[line:913] ERROR mongo_db.save func Error,原因:not master
Traceback (most recent call last):
  File "/home/web/my_env/projects/sq_platform/mongo_db.py", line 904, in save
    save_id = ses.save(save_dict)
  File "/home/web/my_env/lib/python3.5/site-packages/pymongo/collection.py", line 2481, in save
    collation=collation)
  File "/home/web/my_env/lib/python3.5/site-packages/pymongo/collection.py", line 767, in _update
    _check_write_command_response([(0, result)])
  File "/home/web/my_env/lib/python3.5/site-packages/pymongo/helpers.py", line 315, in _check_write_command_response
    raise WriteError(error.get("errmsg"), error.get("code"), error)
pymongo.errors.WriteError: not master
2018-03-19 15:09:42,063 mongo_db.py[line:913] ERROR mongo_db.save func Error,原因:not master
Traceback (most recent call last):
  File "/home/web/my_env/projects/sq_platform/mongo_db.py", line 904, in save
    save_id = ses.save(save_dict)
  File "/home/web/my_env/lib/python3.5/site-packages/pymongo/collection.py", line 2481, in save
    collation=collation)
  File "/home/web/my_env/lib/python3.5/site-packages/pymongo/collection.py", line 767, in _update
    _check_write_command_response([(0, result)])
  File "/home/web/my_env/lib/python3.5/site-packages/pymongo/helpers.py", line 315, in _check_write_command_response
    raise WriteError(error.get("errmsg"), error.get("code"), error)
pymongo.errors.WriteError: not master
